Workbook
Name _qde12: 'Calculos Espesores'!#REF!
Name _qde12: Cargas!$G$15
Name _qde13: 'Calculos Espesores'!#REF!
Name _qde13: Cargas!$G$16
Name _qde14: 'Calculos Espesores'!#REF!
Name _qde14: Cargas!$G$17
Name _qde15: 'Calculos Espesores'!#REF!
Name _qde15: Cargas!$G$18
Name _qde16: 'Calculos Espesores'!#REF!
Name _qde16: Cargas!$G$19
Name _qde17: 'Calculos Espesores'!#REF!
Name _qde17: Cargas!$G$20
Name _qde18: 'Calculos Espesores'!#REF!
Name _qde18: Cargas!$G$21
Name _qde19: 'Calculos Espesores'!#REF!
Name _qde19: Cargas!$G$22
Name _qde20: 'Calculos Espesores'!#REF!
Name _qde20: Cargas!$G$23
Name _qdt10: 'Calculos Espesores'!#REF!
Name _qdt10: Cargas!$G$53
Name _qdt11: 'Calculos Espesores'!#REF!
Name _qdt11: Cargas!$G$54
Name _qdt12: 'Calculos Espesores'!#REF!
Name _qdt12: Cargas!$G$55
Name _qdt13: 'Calculos Espesores'!#REF!
Name _qdt13: Cargas!$G$56
Name _qdt14: 'Calculos Espesores'!#REF!
Name _qdt14: Cargas!$G$57
Name _qdt15: 'Calculos Espesores'!#REF!
Name _qdt15: Cargas!$G$58
Name _qdt16: 'Calculos Espesores'!#REF!
Name _qdt16: Cargas!$G$59
Name _qdt17: 'Calculos Espesores'!#REF!
Name _qdt17: Cargas!$G$60
Name _qdt18: 'Calculos Espesores'!#REF!
Name _qdt18: Cargas!$G$61
Name _qdt19: 'Calculos Espesores'!#REF!
Name _qdt19: Cargas!$G$62
Name _qdt20: 'Calculos Espesores'!#REF!
Name _qdt20: Cargas!$G$63
Name _qdt6: 'Calculos Espesores'!#REF!
Name _qdt6: Cargas!$G$49
Name _qdt7: 'Calculos Espesores'!#REF!
Name _qdt7: Cargas!$G$50
Name _qdt8: 'Calculos Espesores'!#REF!
Name _qdt8: Cargas!$G$51
Name _qdt9: 'Calculos Espesores'!#REF!
Name _qdt9: Cargas!$G$52
Name f_c: '[1]Viga E1 V2'!$D$4
Name f_c: #REF!
Name fy: '[1]Viga E1 V2'!$G$4
Name fy: #REF!
Name qlb: 'Calculos Espesores'!#REF!
Name qlb: Cargas!$F$32
Name qle: 'Calculos Espesores'!#REF!
Name qle: [1]Cargas!$F$26
Name qle: Cargas!$F$31
Name qlt: 'Calculos Espesores'!#REF!
Name qlt: [1]Cargas!$F$52
Name qlt: Cargas!$F$71

Sheet Cargas
C2: INGENIERO DEMO | E2: Proyecto: | G2: Proyecto Demo
C3: INGENIERO CIVIL | E3: Fecha : | G3: 45904
D4: CODIA: 0 | E4: Desc. : | G4: Cuantificación de Cargas
C6: Cuantificación de Sobre Carga
C7: ENTREPISO
C8: Carga Muerta | D8: h (m) | E8: d [ton/m³] | F8: w [ton/m²] | G8: qd (ton/m²)
C9: Losa de 6 | D9: 0.06 | E9: 2.4 | F9: =D9*E9 -> 0.144 | G9: =F9+$F$28+$F$26+$F$27 -> 0.325
C10: Losa de 7 | D10: 0.07 | E10: 2.4 | F10: =D10*E10 -> 0.168 | G10: =F10+$F$28+$F$26+$F$27 -> 0.349
C11: Losa de 8 | D11: 0.08 | E11: 2.4 | F11: =D11*E11 -> 0.192 | G11: =F11+$F$28+$F$26+$F$27 -> 0.373
C12: Losa de 9 | D12: 0.09 | E12: 2.4 | F12: =D12*E12 -> 0.216 | G12: =F12+$F$28+$F$26+$F$27 -> 0.397
C13: Losa de 10 | D13: 0.1 | E13: 2.4 | F13: =D13*E13 -> 0.24 | G13: =F13+$F$28+$F$26+$F$27 -> 0.421
C14: Losa de 11 | D14: 0.11 | E14: 2.4 | F14: =D14*E14 -> 0.264 | G14: =F14+$F$28+$F$26+$F$27 -> 0.445
C15: Losa de 12 | D15: 0.12 | E15: 2.4 | F15: =D15*E15 -> 0.288 | G15: =F15+$F$28+$F$26+$F$27 -> 0.469
C16: Losa de 13 | D16: 0.13 | E16: 2.4 | F16: =D16*E16 -> 0.312 | G16: =F16+$F$28+$F$26+$F$27 -> 0.493
C17: Losa de 14 | D17: 0.14 | E17: 2.4 | F17: =D17*E17 -> 0.336 | G17: =F17+$F$28+$F$26+$F$27 -> 0.517
C18: Losa de 15 | D18: 0.15 | E18: 2.4 | F18: =D18*E18 -> 0.36 | G18: =F18+$F$28+$F$26+$F$27 -> 0.541
C19: Losa de 16 | D19: 0.16 | E19: 2.4 | F19: =D19*E19 -> 0.384 | G19: =F19+$F$28+$F$26+$F$27 -> 0.565
C20: Losa de 17 | D20: 0.17 | E20: 2.4 | F20: =D20*E20 -> 0.408 | G20: =F20+$F$28+$F$26+$F$27 -> 0.589
... C23: Losa de 20 | D23: 0.2 | E23: 2.4 | F23: =D23*E23 -> 0.48 | G23: =F23+$F$28+$F$26+$F$27 -> 0.661
C25: Pesos Propios
C26: Mosaicos | D26: 0.03 | E26: 2.3 | F26: =D26*E26 -> 0.069
C27: Mortero | D27: 0.04 | E27: 1.8 | F27: =D27*E27 -> 0.072
C28: Pañete | D28: 0.02 | E28: 2 | F28: =D28*E28 -> 0.04
C30: Carga Viva
C31: Entrepiso | E31: ql = | F31: 0.2 | G31: ton/m²
C32: Balcones y Escalera | E32: ql = | F32: 0.4 | G32: ton/m²
C34: qu= 1.2qd + 1.6ql | D34: ACI-318-05
C36: Descripción | D36: qd[ton/m²] | E36: ql[ton/m²] | F36: qu[ton/m²]
C37: Interior (h=0.12) | D37: =G15 -> 0.469 | E37: =F31 -> 0.2 | F37: =1.6*E37+1.2*D37 -> 0.8828
C38: Interior (h=0.14) | D38: 0.52 | E38: 0.4 | F38: =1.6*E38+1.2*D38 -> 1.264
C39: Interior (h=0.12)s/pand | D39: =F15+F26+F27+F28 -> 0.469 | E39: 0.2 | F39: =1.6*E39+1.2*D39 -> 0.8828
C42: INGENIERO DEMO | E42: Proyecto: | G42: =G2 -> Proyecto Demo
C43: INGENIERO CIVIL | E43: Fecha : | G43: =G3 -> 45904
D44: CODIA: 0 | E44: Desc. : | G44: Cuantificación de Cargas
C46: Cuantificación de Sobre Carga
C47: TECHO | R47: D | S47: L
C48: Carga Muerta | D48: h (m) | E48: d [ton/m³] | F48: w [ton/m²] | G48: qd (ton/m²) | R48: 1.2 | S48: 1.6
C49: Losa de 6 | D49: 0.06 | E49: 2.4 | F49: =D49*E49 -> 0.144 | G49: =F49+$F$66+$F$67+$F$68 -> 0.328
C50: Losa de 7 | D50: 0.07 | E50: 2.4 | F50: =D50*E50 -> 0.168 | G50: =F50+$F$66+$F$67+$F$68 -> 0.352
C51: Losa de 8 | D51: 0.08 | E51: 2.4 | F51: =D51*E51 -> 0.192 | G51: =F51+$F$66+$F$67+$F$68 -> 0.376
...

Sheet Calculos Espesores
C2: INGENIERO DEMO | E2: Proyecto: | F2: =Cargas!G2 -> Proyecto Demo
C3: INGENIERO CIVIL | E3: Fecha : | F3: =Cargas!G3 -> 45904
D4: CODIA: 0 | E4: Desc. : | F4: Cálculo espesor de losas
C8: Según ACI-318-08 Art. 9.5.2.1 (1 dirección)
C33: Según ACI-318-08 Art. 9.5.3.3 (2 direcciones)

Sheet Espesor Earlette
AB1: {=_xlfn.TEXTAFTER(CELL("filename",S2),"]")} -> Espesor Earlette
B2: INGENIERO DEMO | E2: Proyecto: | G2: =Cargas!G2 -> Proyecto Demo | J2: Pag. | AB2: =_xlfn.TEXTAFTER(AB1,"Espesor") -> Earlette | AC2: =_xlfn.CONCAT(AB2," ","/") -> Earlette /
B3: INGENIERO CIVIL | E3: Fecha : | G3: =Cargas!G3 -> 45904 | J3: 1
B4: CODIA: | C4: 0 | E4: Desc. : | F4: =_xlfn.CONCAT("Espesor"," ","de"," ","Losas"," ",AB2) -> Espesor de Losas Earlette
A6: Cant. de Losas: | B6: =IF(COUNTIFS(C9:C58,"<>1", B9:B58,"<>1")=0, 50, COUNTIFS(C9:C58,"<>1", B9:B58,"<>1")) -> 21 | C6: Fy = | D6: 4200 | E6: Kg/cm²
N7: T | S7: L
A8: LOSA | B8: Lx | C8: Ly | D8: Cond. | E8: K | F8: Ln | G8: b | H8: h [cm] | L8: bw | M8: H | N8: Is | O8: B | P8: yt | Q8: Ib | R8: α | S8: Is | T8: B | U8: yt | V8: Ib | W8: α | X8: T | Y8: L | Z8: αfm | AA8: H
A9: 1 | B9: 6.45 | C9: 5.4 | D9: =IF((MAX(B9:C9)/MIN(B9:C9))>2,"1D","2D") -> 2D | E9: =IF(D9="2D","N.A.",10) -> N.A. | F9: =IF(D9="1D",MIN(B9:C9),MAX(B9:C9)) -> 6.45 | G9: =MAX(B9:C9)/MIN(B9:C9) -> 1.1944444 | H9: =IF(D9="2d",(F9*(0.8+($D$6/14000)))/(36+9*G9),F9/E9) -> 0.15176471 | I9: Usar h = | J9: =MAX(0.12,ROUND(H9,2)) -> 0.15 | L9: 0.3 | M9: 0.6 | N9: =+F9*J9*J9*J9/12 -> 0.0018140625 | O9: =+IF(4*J9>=M9-J9,M9-J9,4*J9)*2+L9 -> 1.2 | P9: =+M9-(0.5*(((O9-L9)*J9*J9)+L9*M9*M9)/((O9-L9)*J9+L9*M9)) -> 0.39642857 | Q9: =+(O9-L9)*J9*J9*J9/12+L9*M9*M9*M9/12+(O9-L9)*J9*POWER(M9-J9*0.5-P9,2)+L9*M9*POWER(P9-0.5*M9,2) -> 0.0095584821 | R9: =+Q9/N9 -> 5.269103 | S9: =+F9*J9*J9*J9*0.5/12 -> 0.00090703125 | T9: =+IF(4*J9>=M9-J9,M9-J9,4*J9)+L9 -> 0.75 | U9: =+M9-(0.5*(((T9-L9)*J9*J9)+L9*M9*M9)/((T9-L9)*J9+L9*M9)) -> 0.36136364 | V9: =+(T9-L9)*J9*J9*J9/12+L9*M9*M9*M9/12+(T9-L9)*J9*POWER(M9-J9*0.5-U9,2)+L9*M9*POWER(U9-0.5*M9,2) -> 0.0080117898 | W9: =+V9/S9 -> 8.832981 | X9: 2 | Y9: 2 | Z9: =+(X9*R9+Y9*W9)/4 -> 7.051042 | AA9: =+(F9*(0.8+($D$6/14000)))/(36+5*((IF(Z9>2,2,Z9))-0.2)*G9) -> 0.15176471
A10: 2 | B10: 4.9 | C10: 4.45 | D10: =IF((MAX(B10:C10)/MIN(B10:C10))>2,"1D","2D") -> 2D | E10: =IF(D10="2D","N.A.",10) -> N.A. | F10: =IF(D10="1D",MIN(B10:C10),MAX(B10:C10)) -> 4.9 | G10: =MAX(B10:C10)/MIN(B10:C10) -> 1.1011236 | H10: =IF(D10="2d",(F10*(0.8+($D$6/14000)))/(36+9*G10),F10/E10) -> 0.11740333 | I10: Usar h = | J10: =MAX(0.12,ROUND(H10,2)) -> 0.12 | L10: 0.3 | M10: 0.6 | N10: =+F10*J10*J10*J10/12 -> 0.0007056 | O10: =+IF(4*J10>=M10-J10,M10-J10,4*J10)*2+L10 -> 1.26 | P10: =+M10-(0.5*(((O10-L10)*J10*J10)+L10*M10*M10)/((O10-L10)*J10+L10*M10)) -> 0.39365854 | Q10: =+(O10-L10)*J10*J10*J10/12+L10*M10*M10*M10/12+(O10-L10)*J10*POWER(M10-J10*0.5-P10,2)+L10*M10*POWER(P10-0.5*M10,2) -> 0.0095842888 | R10: =+Q10/N10 -> 13.583176 | S10: =+F10*J10*J10*J10*0.5/12 -> 0.0003528 | T10: =+IF(4*J10>=M10-J10,M10-J10,4*J10)+L10 -> 0.78 | U10: =+M10-(0.5*(((T10-L10)*J10*J10)+L10*M10*M10)/((T10-L10)*J10+L10*M10)) -> 0.35818182 | V10: =+(T10-L10)*J10*J10*J10/12+L10*M10*M10*M10/12+(T10-L10)*J10*POWER(M10-J10*0.5-U10,2)+L10*M10*POWER(U10-0.5*M10,2) -> 0.0079825745 | W10: =+V10/S10 -> 22.626345 | X10: 2 | Y10: 2 | Z10: =+(X10*R10+Y10*W10)/4 -> 18.10476 | AA10: =+(F10*(0.8+($D$6/14000)))/(36+5*((IF(Z10>2,2,Z10))-0.2)*G10) -> 0.11740333
A11: 3 | B11: 4.9 | C11: 4.4 | D11: =IF((MAX(B11:C11)/MIN(B11:C11))>2,"1D","2D") -> 2D | E11: =IF(D11="2D","N.A.",10) -> N.A. | F11: =IF(D11="1D",MIN(B11:C11),MAX(B11:C11)) -> 4.9 | G11: =MAX(B11:C11)/MIN(B11:C11) -> 1.1136364 | H11: =IF(D11="2d",(F11*(0.8+($D$6/14000)))/(36+9*G11),F11/E11) -> 0.11711605 | I11: Usar h = | J11: =MAX(0.12,ROUND(H11,2)) -> 0.12 | L11: 0.3 | M11: 0.6 | N11: =+F11*J11*J11*J11/12 -> 0.0007056 | O11: =+IF(4*J11>=M11-J11,M11-J11,4*J11)*2+L11 -> 1.26 | P11: =+M11-(0.5*(((O11-L11)*J11*J11)+L11*M11*M11)/((O11-L11)*J11+L11*M11)) -> 0.39365854 | Q11: =+(O11-L11)*J11*J11*J11/12+L11*M11*M11*M11/12+(O11-L11)*J11*POWER(M11-J11*0.5-P11,2)+L11*M11*POWER(P11-0.5*M11,2) -> 0.0095842888 | R11: =+Q11/N11 -> 13.583176 | S11: =+F11*J11*J11*J11*0.5/12 -> 0.0003528 | T11: =+IF(4*J11>=M11-J11,M11-J11,4*J11)+L11 -> 0.78 | U11: =+M11-(0.5*(((T11-L11)*J11*J11)+L11*M11*M11)/((T11-L11)*J11+L11*M11)) -> 0.35818182 | V11: =+(T11-L11)*J11*J11*J11/12+L11*M11*M11*M11/12+(T11-L11)*J11*POWER(M11-J11*0.5-U11,2)+L11*M11*POWER(U11-0.5*M11,2) -> 0.0079825745 | W11: =+V11/S11 -> 22.626345 | X11: 2 | Y11: 2 | Z11: =+(X11*R11+Y11*W11)/4 -> 18.10476 | AA11: =+(F11*(0.8+($D$6/14000)))/(36+5*((IF(Z11>2,2,Z11))-0.2)*G11) -> 0.11711605
A12: 4 | B12: 3.8 | C12: 1.5 | D12: =IF((MAX(B12:C12)/MIN(B12:C12))>2,"1D","2D") -> 1D | E12: 28 | F12: =IF(D12="1D",MIN(B12:C12),MAX(B12:C12)) -> 1.5 | G12: =MAX(B12:C12)/MIN(B12:C12) -> 2.5333333 | H12: =IF(D12="2d",(F12*(0.8+($D$6/14000)))/(36+9*G12),F12/E12) -> 0.053571429 | I12: Usar h = | J12: =MAX(0.12,ROUND(H12,2)) -> 0.12 | L12: 0.3 | M12: 0.6 | N12: =+F12*J12*J12*J12/12 -> 0.000216 | O12: =+IF(4*J12>=M12-J12,M12-J12,4*J12)*2+L12 -> 1.26 | P12: =+M12-(0.5*(((O12-L12)*J12*J12)+L12*M12*M12)/((O12-L12)*J12+L12*M12)) -> 0.39365854 | Q12: =+(O12-L12)*J12*J12*J12/12+L12*M12*M12*M12/12+(O12-L12)*J12*POWER(M12-J12*0.5-P12,2)+L12*M12*POWER(P12-0.5*M12,2) -> 0.0095842888 | R12: =+Q12/N12 -> 44.371707 | S12: =+F12*J12*J12*J12*0.5/12 -> 0.000108 | T12: =+IF(4*J12>=M12-J12,M12-J12,4*J12)+L12 -> 0.78 | U12: =+M12-(0.5*(((T12-L12)*J12*J12)+L12*M12*M12)/((T12-L12)*J12+L12*M12)) -> 0.35818182 | V12: =+(T12-L12)*J12*J12*J12/12+L12*M12*M12*M12/12+(T12-L12)*J12*POWER(M12-J12*0.5-U12,2)+L12*M12*POWER(U12-0.5*M12,2) -> 0.0079825745 | W12: =+V12/S12 -> 73.912727 | X12: 2 | Y12: 2 | Z12: =+(X12*R12+Y12*W12)/4 -> 59.142217 | AA12: =+(F12*(0.8+($D$6/14000)))/(36+5*((IF(Z12>2,2,Z12))-0.2)*G12) -> 0.028061224
A13: 5 | B13: 1.2 | C13: 4.65 | D13: =IF((MAX(B13:C13)/MIN(B13:C13))>2,"1D","2D") -> 1D | E13: 28 | F13: =IF(D13="1D",MIN(B13:C13),MAX(B13:C13)) -> 1.2 | G13: =MAX(B13:C13)/MIN(B13:C13) -> 3.875 | H13: =IF(D13="2d",(F13*(0.8+($D$6/14000)))/(36+9*G13),F13/E13) -> 0.042857143 | I13: Usar h = | J13: =MAX(0.12,ROUND(H13,2)) -> 0.12 | L13: 0.3 | M13: 0.6 | N13: =+F13*J13*J13*J13/12 -> 0.0001728 | O13: =+IF(4*J13>=M13-J13,M13-J13,4*J13)*2+L13 -> 1.26 | P13: =+M13-(0.5*(((O13-L13)*J13*J13)+L13*M13*M13)/((O13-L13)*J13+L13*M13)) -> 0.39365854 | Q13: =+(O13-L13)*J13*J13*J13/12+L13*M13*M13*M13/12+(O13-L13)*J13*POWER(M13-J13*0.5-P13,2)+L13*M13*POWER(P13-0.5*M13,2) -> 0.0095842888 | R13: =+Q13/N13 -> 55.464634 | S13: =+F13*J13*J13*J13*0.5/12 -> 8.64e-05 | T13: =+IF(4*J13>=M13-J13,M13-J13,4*J13)+L13 -> 0.78 | U13: =+M13-(0.5*(((T13-L13)*J13*J13)+L13*M13*M13)/((T13-L13)*J13+L13*M13)) -> 0.35818182 | V13: =+(T13-L13)*J13*J13*J13/12+L13*M13*M13*M13/12+(T13-L13)*J13*POWER(M13-J13*0.5-U13,2)+L13*M13*POWER(U13-0.5*M13,2) -> 0.0079825745 | W13: =+V13/S13 -> 92.390909 | X13: 2 | Y13: 2 | Z13: =+(X13*R13+Y13*W13)/4 -> 73.927772 | AA13: =+(F13*(0.8+($D$6/14000)))/(36+5*((IF(Z13>2,2,Z13))-0.2)*G13) -> 0.018624339
A14: 6 | B14: 7.95 | C14: 7 | D14: =IF((MAX(B14:C14)/MIN(B14:C14))>2,"1D","2D") -> 2D | E14: =IF(D14="2D","N.A.",10) -> N.A. | F14: =IF(D14="1D",MIN(B14:C14),MAX(B14:C14)) -> 7.95 | G14: =MAX(B14:C14)/MIN(B14:C14) -> 1.1357143 | H14: =IF(D14="2d",(F14*(0.8+($D$6/14000)))/(36+9*G14),F14/E14) -> 0.18919796 | I14: Usar h = | J14: 0.2 | L14: 0.3 | M14: 0.6 | N14: =+F14*J14*J14*J14/12 -> 0.0053 | O14: =+IF(4*J14>=M14-J14,M14-J14,4*J14)*2+L14 -> 1.1 | P14: =+M14-(0.5*(((O14-L14)*J14*J14)+L14*M14*M14)/((O14-L14)*J14+L14*M14)) -> 0.39411765 | Q14: =+(O14-L14)*J14*J14*J14/12+L14*M14*M14*M14/12+(O14-L14)*J14*POWER(M14-J14*0.5-P14,2)+L14*M14*POWER(P14-0.5*M14,2) -> 0.0093215686 | R14: =+Q14/N14 -> 1.7587865 | S14: =+F14*J14*J14*J14*0.5/12 -> 0.00265 | T14: =+IF(4*J14>=M14-J14,M14-J14,4*J14)+L14 -> 0.7 | U14: =+M14-(0.5*(((T14-L14)*J14*J14)+L14*M14*M14)/((T14-L14)*J14+L14*M14)) -> 0.36153846 | V14: =+(T14-L14)*J14*J14*J14/12+L14*M14*M14*M14/12+(T14-L14)*J14*POWER(M14-J14*0.5-U14,2)+L14*M14*POWER(U14-0.5*M14,2) -> 0.0078820513 | W14: =+V14/S14 -> 2.974359 | X14: 2 | Y14: 2 | Z14: =+(X14*R14+Y14*W14)/4 -> 2.3665728 | AA14: =+(F14*(0.8+($D$6/14000)))/(36+5*((IF(Z14>2,2,Z14))-0.2)*G14) -> 0.18919796
A15: 7 | B15: 5.55 | C15: 7 | D15: =IF((MAX(B15:C15)/MIN(B15:C15))>2,"1D","2D") -> 2D | E15: =IF(D15="2D","N.A.",10) -> N.A. | F15: =IF(D15="1D",MIN(B15:C15),MAX(B15:C15)) -> 7 | G15: =MAX(B15:C15)/MIN(B15:C15) -> 1.2612613 | H15: =IF(D15="2d",(F15*(0.8+($D$6/14000)))/(36+9*G15),F15/E15) -> 0.16261416 | I15: Usar h = | J15: =MAX(0.12,ROUND(H15,2)) -> 0.16 | L15: 0.3 | M15: 0.6 | N15: =+F15*J15*J15*J15/12 -> 0.0023893333 | O15: =+IF(4*J15>=M15-J15,M15-J15,4*J15)*2+L15 -> 1.18 | P15: =+M15-(0.5*(((O15-L15)*J15*J15)+L15*M15*M15)/((O15-L15)*J15+L15*M15)) -> 0.3965586 | Q15: =+(O15-L15)*J15*J15*J15/12+L15*M15*M15*M15/12+(O15-L15)*J15*POWER(M15-J15*0.5-P15,2)+L15*M15*POWER(P15-0.5*M15,2) -> 0.009524094 | R15: =+Q15/N15 -> 3.9860885 | S15: =+F15*J15*J15*J15*0.5/12 -> 0.0011946667 | T15: =+IF(4*J15>=M15-J15,M15-J15,4*J15)+L15 -> 0.74 | U15: =+M15-(0.5*(((T15-L15)*J15*J15)+L15*M15*M15)/((T15-L15)*J15+L15*M15)) -> 0.36185304 | V15: =+(T15-L15)*J15*J15*J15/12+L15*M15*M15*M15/12+(T15-L15)*J15*POWER(M15-J15*0.5-U15,2)+L15*M15*POWER(U15-0.5*M15,2) -> 0.0079995669 | W15: =+V15/S15 -> 6.696066 | X15: 2 | Y15: 2 | Z15: =+(X15*R15+Y15*W15)/4 -> 5.3410772 | AA15: =+(F15*(0.8+($D$6/14000)))/(36+5*((IF(Z15>2,2,Z15))-0.2)*G15) -> 0.16261416
A16: 8 | B16: 1.7 | C16: 2 | D16: =IF((MAX(B16:C16)/MIN(B16:C16))>2,"1D","2D") -> 2D | E16: =IF(D16="2D","N.A.",10) -> N.A. | F16: =IF(D16="1D",MIN(B16:C16),MAX(B16:C16)) -> 2 | G16: =MAX(B16:C16)/MIN(B16:C16) -> 1.1764706 | H16: =IF(D16="2d",(F16*(0.8+($D$6/14000)))/(36+9*G16),F16/E16) -> 0.047222222 | I16: Usar h = | J16: =MAX(0.12,ROUND(H16,2)) -> 0.12 | L16: 0.3 | M16: 0.6 | N16: =+F16*J16*J16*J16/12 -> 0.000288 | O16: =+IF(4*J16>=M16-J16,M16-J16,4*J16)*2+L16 -> 1.26 | P16: =+M16-(0.5*(((O16-L16)*J16*J16)+L16*M16*M16)/((O16-L16)*J16+L16*M16)) -> 0.39365854 | Q16: =+(O16-L16)*J16*J16*J16/12+L16*M16*M16*M16/12+(O16-L16)*J16*POWER(M16-J16*0.5-P16,2)+L16*M16*POWER(P16-0.5*M16,2) -> 0.0095842888 | R16: =+Q16/N16 -> 33.27878 | S16: =+F16*J16*J16*J16*0.5/12 -> 0.000144 | T16: =+IF(4*J16>=M16-J16,M16-J16,4*J16)+L16 -> 0.78 | U16: =+M16-(0.5*(((T16-L16)*J16*J16)+L16*M16*M16)/((T16-L16)*J16+L16*M16)) -> 0.35818182 | V16: =+(T16-L16)*J16*J16*J16/12+L16*M16*M16*M16/12+(T16-L16)*J16*POWER(M16-J16*0.5-U16,2)+L16*M16*POWER(U16-0.5*M16,2) -> 0.0079825745 | W16: =+V16/S16 -> 55.434545 | X16: 2 | Y16: 2 | Z16: =+(X16*R16+Y16*W16)/4 -> 44.356663 | AA16: =+(F16*(0.8+($D$6/14000)))/(36+5*((IF(Z16>2,2,Z16))-0.2)*G16) -> 0.047222222
A17: 9 | B17: 2.5 | C17: 2 | D17: =IF((MAX(B17:C17)/MIN(B17:C17))>2,"1D","2D") -> 2D | E17: =IF(D17="2D","N.A.",10) -> N.A. | F17: =IF(D17="1D",MIN(B17:C17),MAX(B17:C17)) -> 2.5 | G17: =MAX(B17:C17)/MIN(B17:C17) -> 1.25 | H17: =IF(D17="2d",(F17*(0.8+($D$6/14000)))/(36+9*G17),F17/E17) -> 0.058201058 | I17: Usar h = | J17: =MAX(0.12,ROUND(H17,2)) -> 0.12 | L17: 0.3 | M17: 0.6 | N17: =+F17*J17*J17*J17/12 -> 0.00036 | O17: =+IF(4*J17>=M17-J17,M17-J17,4*J17)*2+L17 -> 1.26 | P17: =+M17-(0.5*(((O17-L17)*J17*J17)+L17*M17*M17)/((O17-L17)*J17+L17*M17)) -> 0.39365854 | Q17: =+(O17-L17)*J17*J17*J17/12+L17*M17*M17*M17/12+(O17-L17)*J17*POWER(M17-J17*0.5-P17,2)+L17*M17*POWER(P17-0.5*M17,2) -> 0.0095842888 | R17: =+Q17/N17 -> 26.623024 | S17: =+F17*J17*J17*J17*0.5/12 -> 0.00018 | T17: =+IF(4*J17>=M17-J17,M17-J17,4*J17)+L17 -> 0.78 | U17: =+M17-(0.5*(((T17-L17)*J17*J17)+L17*M17*M17)/((T17-L17)*J17+L17*M17)) -> 0.35818182 | V17: =+(T17-L17)*J17*J17*J17/12+L17*M17*M17*M17/12+(T17-L17)*J17*POWER(M17-J17*0.5-U17,2)+L17*M17*POWER(U17-0.5*M17,2) -> 0.0079825745 | W17: =+V17/S17 -> 44.347636 | X17: 2 | Y17: 2 | Z17: =+(X17*R17+Y17*W17)/4 -> 35.48533 | AA17: =+(F17*(0.8+($D$6/14000)))/(36+5*((IF(Z17>2,2,Z17))-0.2)*G17) -> 0.058201058
A18: 10 | B18: 3.6 | C18: 1.7 | D18: =IF((MAX(B18:C18)/MIN(B18:C18))>2,"1D","2D") -> 1D | E18: 28 | F18: =IF(D18="1D",MIN(B18:C18),MAX(B18:C18)) -> 1.7 | G18: =MAX(B18:C18)/MIN(B18:C18) -> 2.1176471 | H18: =IF(D18="2d",(F18*(0.8+($D$6/14000)))/(36+9*G18),F18/E18) -> 0.060714286 | I18: Usar h = | J18: 0.12 | L18: 0.3 | M18: 0.6 | N18: =+F18*J18*J18*J18/12 -> 0.0002448 | O18: =+IF(4*J18>=M18-J18,M18-J18,4*J18)*2+L18 -> 1.26 | P18: =+M18-(0.5*(((O18-L18)*J18*J18)+L18*M18*M18)/((O18-L18)*J18+L18*M18)) -> 0.39365854 | Q18: =+(O18-L18)*J18*J18*J18/12+L18*M18*M18*M18/12+(O18-L18)*J18*POWER(M18-J18*0.5-P18,2)+L18*M18*POWER(P18-0.5*M18,2) -> 0.0095842888 | R18: =+Q18/N18 -> 39.151506 | S18: =+F18*J18*J18*J18*0.5/12 -> 0.0001224 | T18: =+IF(4*J18>=M18-J18,M18-J18,4*J18)+L18 -> 0.78 | U18: =+M18-(0.5*(((T18-L18)*J18*J18)+L18*M18*M18)/((T18-L18)*J18+L18*M18)) -> 0.35818182 | V18: =+(T18-L18)*J18*J18*J18/12+L18*M18*M18*M18/12+(T18-L18)*J18*POWER(M18-J18*0.5-U18,2)+L18*M18*POWER(U18-0.5*M18,2) -> 0.0079825745 | W18: =+V18/S18 -> 65.217112 | X18: 2 | Y18: 2 | Z18: =+(X18*R18+Y18*W18)/4 -> 52.184309 | AA18: =+(F18*(0.8+($D$6/14000)))/(36+5*((IF(Z18>2,2,Z18))-0.2)*G18) -> 0.033963675
A19: 11 | B19: 1.2 | C19: 4.6 | D19: =IF((MAX(B19:C19)/MIN(B19:C19))>2,"1D","2D") -> 1D | E19: 28 | F19: =IF(D19="1D",MIN(B19:C19),MAX(B19:C19)) -> 1.2 | G19: =MAX(B19:C19)/MIN(B19:C19) -> 3.8333333 | H19: =IF(D19="2d",(F19*(0.8+($D$6/14000)))/(36+9*G19),F19/E19) -> 0.042857143 | I19: Usar h = | J19: =MAX(0.12,ROUND(H19,2)) -> 0.12 | L19: 0.3 | M19: 0.6 | N19: =+F19*J19*J19*J19/12 -> 0.0001728 | O19: =+IF(4*J19>=M19-J19,M19-J19,4*J19)*2+L19 -> 1.26 | P19: =+M19-(0.5*(((O19-L19)*J19*J19)+L19*M19*M19)/((O19-L19)*J19+L19*M19)) -> 0.39365854 | Q19: =+(O19-L19)*J19*J19*J19/12+L19*M19*M19*M19/12+(O19-L19)*J19*POWER(M19-J19*0.5-P19,2)+L19*M19*POWER(P19-0.5*M19,2) -> 0.0095842888 | R19: =+Q19/N19 -> 55.464634 | S19: =+F19*J19*J19*J19*0.5/12 -> 8.64e-05 | T19: =+IF(4*J19>=M19-J19,M19-J19,4*J19)+L19 -> 0.78 | U19: =+M19-(0.5*(((T19-L19)*J19*J19)+L19*M19*M19)/((T19-L19)*J19+L19*M19)) -> 0.35818182 | V19: =+(T19-L19)*J19*J19*J19/12+L19*M19*M19*M19/12+(T19-L19)*J19*POWER(M19-J19*0.5-U19,2)+L19*M19*POWER(U19-0.5*M19,2) -> 0.0079825745 | W19: =+V19/S19 -> 92.390909 | X19: 2 | Y19: 2 | Z19: =+(X19*R19+Y19*W19)/4 -> 73.927772 | AA19: =+(F19*(0.8+($D$6/14000)))/(36+5*((IF(Z19>2,2,Z19))-0.2)*G19) -> 0.018723404
A20: 12 | B20: 4.7 | C20: 4.45 | D20: =IF((MAX(B20:C20)/MIN(B20:C20))>2,"1D","2D") -> 2D | E20: =IF(D20="2D","N.A.",10) -> N.A. | F20: =IF(D20="1D",MIN(B20:C20),MAX(B20:C20)) -> 4.7 | G20: =MAX(B20:C20)/MIN(B20:C20) -> 1.0561798 | H20: =IF(D20="2d",(F20*(0.8+($D$6/14000)))/(36+9*G20),F20/E20) -> 0.11361235 | I20: Usar h = | J20: =MAX(0.12,ROUND(H20,2)) -> 0.12 | L20: 0.3 | M20: 0.6 | N20: =+F20*J20*J20*J20/12 -> 0.0006768 | O20: =+IF(4*J20>=M20-J20,M20-J20,4*J20)*2+L20 -> 1.26 | P20: =+M20-(0.5*(((O20-L20)*J20*J20)+L20*M20*M20)/((O20-L20)*J20+L20*M20)) -> 0.39365854 | Q20: =+(O20-L20)*J20*J20*J20/12+L20*M20*M20*M20/12+(O20-L20)*J20*POWER(M20-J20*0.5-P20,2)+L20*M20*POWER(P20-0.5*M20,2) -> 0.0095842888 | R20: =+Q20/N20 -> 14.161183 | S20: =+F20*J20*J20*J20*0.5/12 -> 0.0003384 | T20: =+IF(4*J20>=M20-J20,M20-J20,4*J20)+L20 -> 0.78 | U20: =+M20-(0.5*(((T20-L20)*J20*J20)+L20*M20*M20)/((T20-L20)*J20+L20*M20)) -> 0.35818182 | V20: =+(T20-L20)*J20*J20*J20/12+L20*M20*M20*M20/12+(T20-L20)*J20*POWER(M20-J20*0.5-U20,2)+L20*M20*POWER(U20-0.5*M20,2) -> 0.0079825745 | W20: =+V20/S20 -> 23.589168 | X20: 2 | Y20: 2 | Z20: =+(X20*R20+Y20*W20)/4 -> 18.875176 | AA20: =+(F20*(0.8+($D$6/14000)))/(36+5*((IF(Z20>2,2,Z20))-0.2)*G20) -> 0.11361235
A21: 13 | B21: 4.2 | C21: 5 | D21: =IF((MAX(B21:C21)/MIN(B21:C21))>2,"1D","2D") -> 2D | E21: =IF(D21="2D","N.A.",10) -> N.A. | F21: =IF(D21="1D",MIN(B21:C21),MAX(B21:C21)) -> 5 | G21: =MAX(B21:C21)/MIN(B21:C21) -> 1.1904762 | H21: =IF(D21="2d",(F21*(0.8+($D$6/14000)))/(36+9*G21),F21/E21) -> 0.117737 | I21: Usar h = | J21: =MAX(0.12,ROUND(H21,2)) -> 0.12 | L21: 0.3 | M21: 0.6 | N21: =+F21*J21*J21*J21/12 -> 0.00072 | O21: =+IF(4*J21>=M21-J21,M21-J21,4*J21)*2+L21 -> 1.26 | P21: =+M21-(0.5*(((O21-L21)*J21*J21)+L21*M21*M21)/((O21-L21)*J21+L21*M21)) -> 0.39365854 | Q21: =+(O21-L21)*J21*J21*J21/12+L21*M21*M21*M21/12+(O21-L21)*J21*POWER(M21-J21*0.5-P21,2)+L21*M21*POWER(P21-0.5*M21,2) -> 0.0095842888 | R21: =+Q21/N21 -> 13.311512 | S21: =+F21*J21*J21*J21*0.5/12 -> 0.00036 | T21: =+IF(4*J21>=M21-J21,M21-J21,4*J21)+L21 -> 0.78 | U21: =+M21-(0.5*(((T21-L21)*J21*J21)+L21*M21*M21)/((T21-L21)*J21+L21*M21)) -> 0.35818182 | V21: =+(T21-L21)*J21*J21*J21/12+L21*M21*M21*M21/12+(T21-L21)*J21*POWER(M21-J21*0.5-U21,2)+L21*M21*POWER(U21-0.5*M21,2) -> 0.0079825745 | W21: =+V21/S21 -> 22.173818 | X21: 2 | Y21: 2 | Z21: =+(X21*R21+Y21*W21)/4 -> 17.742665 | AA21: =+(F21*(0.8+($D$6/14000)))/(36+5*((IF(Z21>2,2,Z21))-0.2)*G21) -> 0.117737
A22: 14 | B22: 4.7 | C22: 4.3 | D22: =IF((MAX(B22:C22)/MIN(B22:C22))>2,"1D","2D") -> 2D | E22: =IF(D22="2D","N.A.",10) -> N.A. | F22: =IF(D22="1D",MIN(B22:C22),MAX(B22:C22)) -> 4.7 | G22: =MAX(B22:C22)/MIN(B22:C22) -> 1.0930233 | H22: =IF(D22="2d",(F22*(0.8+($D$6/14000)))/(36+9*G22),F22/E22) -> 0.11279046 | I22: Usar h = | J22: =MAX(0.12,ROUND(H22,2)) -> 0.12 | L22: 0.3 | M22: 0.6 | N22: =+F22*J22*J22*J22/12 -> 0.0006768 | O22: =+IF(4*J22>=M22-J22,M22-J22,4*J22)*2+L22 -> 1.26 | P22: =+M22-(0.5*(((O22-L22)*J22*J22)+L22*M22*M22)/((O22-L22)*J22+L22*M22)) -> 0.39365854 | Q22: =+(O22-L22)*J22*J22*J22/12+L22*M22*M22*M22/12+(O22-L22)*J22*POWER(M22-J22*0.5-P22,2)+L22*M22*POWER(P22-0.5*M22,2) -> 0.0095842888 | R22: =+Q22/N22 -> 14.161183 | S22: =+F22*J22*J22*J22*0.5/12 -> 0.0003384 | T22: =+IF(4*J22>=M22-J22,M22-J22,4*J22)+L22 -> 0.78 | U22: =+M22-(0.5*(((T22-L22)*J22*J22)+L22*M22*M22)/((T22-L22)*J22+L22*M22)) -> 0.35818182 | V22: =+(T22-L22)*J22*J22*J22/12+L22*M22*M22*M22/12+(T22-L22)*J22*POWER(M22-J22*0.5-U22,2)+L22*M22*POWER(U22-0.5*M22,2) -> 0.0079825745 | W22: =+V22/S22 -> 23.589168 | X22: 2 | Y22: 2 | Z22: =+(X22*R22+Y22*W22)/4 -> 18.875176 | AA22: =+(F22*(0.8+($D$6/14000)))/(36+5*((IF(Z22>2,2,Z22))-0.2)*G22) -> 0.11279046
A23: 15 | B23: 1.2 | C23: 6 | D23: =IF((MAX(B23:C23)/MIN(B23:C23))>2,"1D","2D") -> 1D | E23: 28 | F23: =IF(D23="1D",MIN(B23:C23),MAX(B23:C23)) -> 1.2 | G23: =MAX(B23:C23)/MIN(B23:C23) -> 5 | H23: =IF(D23="2d",(F23*(0.8+($D$6/14000)))/(36+9*G23),F23/E23) -> 0.042857143 | I23: Usar h = | J23: =MAX(0.12,ROUND(H23,2)) -> 0.12 | L23: 0.3 | M23: 0.6 | N23: =+F23*J23*J23*J23/12 -> 0.0001728 | O23: =+IF(4*J23>=M23-J23,M23-J23,4*J23)*2+L23 -> 1.26 | P23: =+M23-(0.5*(((O23-L23)*J23*J23)+L23*M23*M23)/((O23-L23)*J23+L23*M23)) -> 0.39365854 | Q23: =+(O23-L23)*J23*J23*J23/12+L23*M23*M23*M23/12+(O23-L23)*J23*POWER(M23-J23*0.5-P23,2)+L23*M23*POWER(P23-0.5*M23,2) -> 0.0095842888 | R23: =+Q23/N23 -> 55.464634 | S23: =+F23*J23*J23*J23*0.5/12 -> 8.64e-05 | T23: =+IF(4*J23>=M23-J23,M23-J23,4*J23)+L23 -> 0.78 | U23: =+M23-(0.5*(((T23-L23)*J23*J23)+L23*M23*M23)/((T23-L23)*J23+L23*M23)) -> 0.35818182 | V23: =+(T23-L23)*J23*J23*J23/12+L23*M23*M23*M23/12+(T23-L23)*J23*POWER(M23-J23*0.5-U23,2)+L23*M23*POWER(U23-0.5*M23,2) -> 0.0079825745 | W23: =+V23/S23 -> 92.390909 | X23: 2 | Y23: 2 | Z23: =+(X23*R23+Y23*W23)/4 -> 73.927772 | AA23: =+(F23*(0.8+($D$6/14000)))/(36+5*((IF(Z23>2,2,Z23))-0.2)*G23) -> 0.016296296
A24: 16 | B24: 4.7 | C24: 4.8 | D24: =IF((MAX(B24:C24)/MIN(B24:C24))>2,"1D","2D") -> 2D | E24: =IF(D24="2D","N.A.",10) -> N.A. | F24: =IF(D24="1D",MIN(B24:C24),MAX(B24:C24)) -> 4.8 | G24: =MAX(B24:C24)/MIN(B24:C24) -> 1.0212766 | H24: =IF(D24="2d",(F24*(0.8+($D$6/14000)))/(36+9*G24),F24/E24) -> 0.11683616 | I24: Usar h = | J24: =MAX(0.12,ROUND(H24,2)) -> 0.12 | L24: 0.3 | M24: 0.6 | N24: =+F24*J24*J24*J24/12 -> 0.0006912 | O24: =+IF(4*J24>=M24-J24,M24-J24,4*J24)*2+L24 -> 1.26 | P24: =+M24-(0.5*(((O24-L24)*J24*J24)+L24*M24*M24)/((O24-L24)*J24+L24*M24)) -> 0.39365854 | Q24: =+(O24-L24)*J24*J24*J24/12+L24*M24*M24*M24/12+(O24-L24)*J24*POWER(M24-J24*0.5-P24,2)+L24*M24*POWER(P24-0.5*M24,2) -> 0.0095842888 | R24: =+Q24/N24 -> 13.866159 | S24: =+F24*J24*J24*J24*0.5/12 -> 0.0003456 | T24: =+IF(4*J24>=M24-J24,M24-J24,4*J24)+L24 -> 0.78 | U24: =+M24-(0.5*(((T24-L24)*J24*J24)+L24*M24*M24)/((T24-L24)*J24+L24*M24)) -> 0.35818182 | V24: =+(T24-L24)*J24*J24*J24/12+L24*M24*M24*M24/12+(T24-L24)*J24*POWER(M24-J24*0.5-U24,2)+L24*M24*POWER(U24-0.5*M24,2) -> 0.0079825745 | W24: =+V24/S24 -> 23.097727 | X24: 2 | Y24: 2 | Z24: =+(X24*R24+Y24*W24)/4 -> 18.481943 | AA24: =+(F24*(0.8+($D$6/14000)))/(36+5*((IF(Z24>2,2,Z24))-0.2)*G24) -> 0.11683616
A25: 17 | B25: 3.4 | C25: 2.5 | D25: =IF((MAX(B25:C25)/MIN(B25:C25))>2,"1D","2D") -> 2D | E25: =IF(D25="2D","N.A.",10) -> N.A. | F25: =IF(D25="1D",MIN(B25:C25),MAX(B25:C25)) -> 3.4 | G25: =MAX(B25:C25)/MIN(B25:C25) -> 1.36 | H25: =IF(D25="2d",(F25*(0.8+($D$6/14000)))/(36+9*G25),F25/E25) -> 0.077529022 | I25: Usar h = | J25: =MAX(0.12,ROUND(H25,2)) -> 0.12 | L25: 0.3 | M25: 0.6 | N25: =+F25*J25*J25*J25/12 -> 0.0004896 | O25: =+IF(4*J25>=M25-J25,M25-J25,4*J25)*2+L25 -> 1.26 | P25: =+M25-(0.5*(((O25-L25)*J25*J25)+L25*M25*M25)/((O25-L25)*J25+L25*M25)) -> 0.39365854 | Q25: =+(O25-L25)*J25*J25*J25/12+L25*M25*M25*M25/12+(O25-L25)*J25*POWER(M25-J25*0.5-P25,2)+L25*M25*POWER(P25-0.5*M25,2) -> 0.0095842888 | R25: =+Q25/N25 -> 19.575753 | S25: =+F25*J25*J25*J25*0.5/12 -> 0.0002448 | T25: =+IF(4*J25>=M25-J25,M25-J25,4*J25)+L25 -> 0.78 | U25: =+M25-(0.5*(((T25-L25)*J25*J25)+L25*M25*M25)/((T25-L25)*J25+L25*M25)) -> 0.35818182 | V25: =+(T25-L25)*J25*J25*J25/12+L25*M25*M25*M25/12+(T25-L25)*J25*POWER(M25-J25*0.5-U25,2)+L25*M25*POWER(U25-0.5*M25,2) -> 0.0079825745 | W25: =+V25/S25 -> 32.608556 | X25: 2 | Y25: 2 | Z25: =+(X25*R25+Y25*W25)/4 -> 26.092155 | AA25: =+(F25*(0.8+($D$6/14000)))/(36+5*((IF(Z25>2,2,Z25))-0.2)*G25) -> 0.077529022
A26: 18 | B26: 1.7 | C26: 2.5 | D26: =IF((MAX(B26:C26)/MIN(B26:C26))>2,"1D","2D") -> 2D | E26: =IF(D26="2D","N.A.",10) -> N.A. | F26: =IF(D26="1D",MIN(B26:C26),MAX(B26:C26)) -> 2.5 | G26: =MAX(B26:C26)/MIN(B26:C26) -> 1.4705882 | H26: =IF(D26="2d",(F26*(0.8+($D$6/14000)))/(36+9*G26),F26/E26) -> 0.055854241 | I26: Usar h = | J26: =MAX(0.12,ROUND(H26,2)) -> 0.12 | L26: 0.3 | M26: 0.6 | N26: =+F26*J26*J26*J26/12 -> 0.00036 | O26: =+IF(4*J26>=M26-J26,M26-J26,4*J26)*2+L26 -> 1.26 | P26: =+M26-(0.5*(((O26-L26)*J26*J26)+L26*M26*M26)/((O26-L26)*J26+L26*M26)) -> 0.39365854 | Q26: =+(O26-L26)*J26*J26*J26/12+L26*M26*M26*M26/12+(O26-L26)*J26*POWER(M26-J26*0.5-P26,2)+L26*M26*POWER(P26-0.5*M26,2) -> 0.0095842888 | R26: =+Q26/N26 -> 26.623024 | S26: =+F26*J26*J26*J26*0.5/12 -> 0.00018 | T26: =+IF(4*J26>=M26-J26,M26-J26,4*J26)+L26 -> 0.78 | U26: =+M26-(0.5*(((T26-L26)*J26*J26)+L26*M26*M26)/((T26-L26)*J26+L26*M26)) -> 0.35818182 | V26: =+(T26-L26)*J26*J26*J26/12+L26*M26*M26*M26/12+(T26-L26)*J26*POWER(M26-J26*0.5-U26,2)+L26*M26*POWER(U26-0.5*M26,2) -> 0.0079825745 | W26: =+V26/S26 -> 44.347636 | X26: 2 | Y26: 2 | Z26: =+(X26*R26+Y26*W26)/4 -> 35.48533 | AA26: =+(F26*(0.8+($D$6/14000)))/(36+5*((IF(Z26>2,2,Z26))-0.2)*G26) -> 0.055854241
A27: 19 | B27: 4.7 | C27: 4.6 | D27: =IF((MAX(B27:C27)/MIN(B27:C27))>2,"1D","2D") -> 2D | E27: =IF(D27="2D","N.A.",10) -> N.A. | F27: =IF(D27="1D",MIN(B27:C27),MAX(B27:C27)) -> 4.7 | G27: =MAX(B27:C27)/MIN(B27:C27) -> 1.0217391 | H27: =IF(D27="2d",(F27*(0.8+($D$6/14000)))/(36+9*G27),F27/E27) -> 0.11439153 | I27: Usar h = | J27: =MAX(0.12,ROUND(H27,2)) -> 0.12 | L27: 0.3 | M27: 0.6 | N27: =+F27*J27*J27*J27/12 -> 0.0006768 | O27: =+IF(4*J27>=M27-J27,M27-J27,4*J27)*2+L27 -> 1.26 | P27: =+M27-(0.5*(((O27-L27)*J27*J27)+L27*M27*M27)/((O27-L27)*J27+L27*M27)) -> 0.39365854 | Q27: =+(O27-L27)*J27*J27*J27/12+L27*M27*M27*M27/12+(O27-L27)*J27*POWER(M27-J27*0.5-P27,2)+L27*M27*POWER(P27-0.5*M27,2) -> 0.0095842888 | R27: =+Q27/N27 -> 14.161183 | S27: =+F27*J27*J27*J27*0.5/12 -> 0.0003384 | T27: =+IF(4*J27>=M27-J27,M27-J27,4*J27)+L27 -> 0.78 | U27: =+M27-(0.5*(((T27-L27)*J27*J27)+L27*M27*M27)/((T27-L27)*J27+L27*M27)) -> 0.35818182 | V27: =+(T27-L27)*J27*J27*J27/12+L27*M27*M27*M27/12+(T27-L27)*J27*POWER(M27-J27*0.5-U27,2)+L27*M27*POWER(U27-0.5*M27,2) -> 0.0079825745 | W27: =+V27/S27 -> 23.589168 | X27: 2 | Y27: 2 | Z27: =+(X27*R27+Y27*W27)/4 -> 18.875176 | AA27: =+(F27*(0.8+($D$6/14000)))/(36+5*((IF(Z27>2,2,Z27))-0.2)*G27) -> 0.11439153
A28: 20 | B28: 1.5 | C28: 1.8 | D28: =IF((MAX(B28:C28)/MIN(B28:C28))>2,"1D","2D") -> 2D | E28: =IF(D28="2D","N.A.",10) -> N.A. | F28: =IF(D28="1D",MIN(B28:C28),MAX(B28:C28)) -> 1.8 | G28: =MAX(B28:C28)/MIN(B28:C28) -> 1.2 | H28: =IF(D28="2d",(F28*(0.8+($D$6/14000)))/(36+9*G28),F28/E28) -> 0.042307692 | I28: Usar h = | J28: =MAX(0.12,ROUND(H28,2)) -> 0.12 | L28: 0.3 | M28: 0.6 | N28: =+F28*J28*J28*J28/12 -> 0.0002592 | O28: =+IF(4*J28>=M28-J28,M28-J28,4*J28)*2+L28 -> 1.26 | P28: =+M28-(0.5*(((O28-L28)*J28*J28)+L28*M28*M28)/((O28-L28)*J28+L28*M28)) -> 0.39365854 | Q28: =+(O28-L28)*J28*J28*J28/12+L28*M28*M28*M28/12+(O28-L28)*J28*POWER(M28-J28*0.5-P28,2)+L28*M28*POWER(P28-0.5*M28,2) -> 0.0095842888 | R28: =+Q28/N28 -> 36.976423 | S28: =+F28*J28*J28*J28*0.5/12 -> 0.0001296 | T28: =+IF(4*J28>=M28-J28,M28-J28,4*J28)+L28 -> 0.78 | U28: =+M28-(0.5*(((T28-L28)*J28*J28)+L28*M28*M28)/((T28-L28)*J28+L28*M28)) -> 0.35818182 | V28: =+(T28-L28)*J28*J28*J28/12+L28*M28*M28*M28/12+(T28-L28)*J28*POWER(M28-J28*0.5-U28,2)+L28*M28*POWER(U28-0.5*M28,2) -> 0.0079825745 | W28: =+V28/S28 -> 61.593939 | X28: 2 | Y28: 2 | Z28: =+(X28*R28+Y28*W28)/4 -> 49.285181 | AA28: =+(F28*(0.8+($D$6/14000)))/(36+5*((IF(Z28>2,2,Z28))-0.2)*G28) -> 0.042307692
A29: 21 | B29: 3 | C29: 3.1 | D29: =IF((MAX(B29:C29)/MIN(B29:C29))>2,"1D","2D") -> 2D | E29: =IF(D29="2D","N.A.",10) -> N.A. | F29: =IF(D29="1D",MIN(B29:C29),MAX(B29:C29)) -> 3.1 | G29: =MAX(B29:C29)/MIN(B29:C29) -> 1.0333333 | H29: =IF(D29="2d",(F29*(0.8+($D$6/14000)))/(36+9*G29),F29/E29) -> 0.075275938 | I29: Usar h = | J29: =MAX(0.12,ROUND(H29,2)) -> 0.12 | L29: 0.3 | M29: 0.6 | N29: =+F29*J29*J29*J29/12 -> 0.0004464 | O29: =+IF(4*J29>=M29-J29,M29-J29,4*J29)*2+L29 -> 1.26 | P29: =+M29-(0.5*(((O29-L29)*J29*J29)+L29*M29*M29)/((O29-L29)*J29+L29*M29)) -> 0.39365854 | Q29: =+(O29-L29)*J29*J29*J29/12+L29*M29*M29*M29/12+(O29-L29)*J29*POWER(M29-J29*0.5-P29,2)+L29*M29*POWER(P29-0.5*M29,2) -> 0.0095842888 | R29: =+Q29/N29 -> 21.470181 | S29: =+F29*J29*J29*J29*0.5/12 -> 0.0002232 | T29: =+IF(4*J29>=M29-J29,M29-J29,4*J29)+L29 -> 0.78 | U29: =+M29-(0.5*(((T29-L29)*J29*J29)+L29*M29*M29)/((T29-L29)*J29+L29*M29)) -> 0.35818182 | V29: =+(T29-L29)*J29*J29*J29/12+L29*M29*M29*M29/12+(T29-L29)*J29*POWER(M29-J29*0.5-U29,2)+L29*M29*POWER(U29-0.5*M29,2) -> 0.0079825745 | W29: =+V29/S29 -> 35.764223 | X29: 2 | Y29: 2 | Z29: =+(X29*R29+Y29*W29)/4 -> 28.617202 | AA29: =+(F29*(0.8+($D$6/14000)))/(36+5*((IF(Z29>2,2,Z29))-0.2)*G29) -> 0.075275938
A30: 22 | B30: 1 | C30: 1 | D30: =IF((MAX(B30:C30)/MIN(B30:C30))>2,"1D","2D") -> 2D | E30: =IF(D30="2D","N.A.",10) -> N.A. | F30: =IF(D30="1D",MIN(B30:C30),MAX(B30:C30)) -> 1 | G30: =MAX(B30:C30)/MIN(B30:C30) -> 1 | H30: =IF(D30="2d",(F30*(0.8+($D$6/14000)))/(36+9*G30),F30/E30) -> 0.024444444 | I30: Usar h = | J30: =MAX(0.12,ROUND(H30,2)) -> 0.12 | L30: 0.3 | M30: 0.6 | N30: =+F30*J30*J30*J30/12 -> 0.000144 | O30: =+IF(4*J30>=M30-J30,M30-J30,4*J30)*2+L30 -> 1.26 | P30: =+M30-(0.5*(((O30-L30)*J30*J30)+L30*M30*M30)/((O30-L30)*J30+L30*M30)) -> 0.39365854 | Q30: =+(O30-L30)*J30*J30*J30/12+L30*M30*M30*M30/12+(O30-L30)*J30*POWER(M30-J30*0.5-P30,2)+L30*M30*POWER(P30-0.5*M30,2) -> 0.0095842888 | R30: =+Q30/N30 -> 66.557561 | S30: =+F30*J30*J30*J30*0.5/12 -> 7.2e-05 | T30: =+IF(4*J30>=M30-J30,M30-J30,4*J30)+L30 -> 0.78 | U30: =+M30-(0.5*(((T30-L30)*J30*J30)+L30*M30*M30)/((T30-L30)*J30+L30*M30)) -> 0.35818182 | V30: =+(T30-L30)*J30*J30*J30/12+L30*M30*M30*M30/12+(T30-L30)*J30*POWER(M30-J30*0.5-U30,2)+L30*M30*POWER(U30-0.5*M30,2) -> 0.0079825745 | W30: =+V30/S30 -> 110.86909 | X30: 2 | Y30: 2 | Z30: =+(X30*R30+Y30*W30)/4 -> 88.713326 | AA30: =+(F30*(0.8+($D$6/14000)))/(36+5*((IF(Z30>2,2,Z30))-0.2)*G30) -> 0.024444444
A31: 23 | B31: 1 | C31: 1 | D31: =IF((MAX(B31:C31)/MIN(B31:C31))>2,"1D","2D") -> 2D | E31: =IF(D31="2D","N.A.",10) -> N.A. | F31: =IF(D31="1D",MIN(B31:C31),MAX(B31:C31)) -> 1 | G31: =MAX(B31:C31)/MIN(B31:C31) -> 1 | H31: =IF(D31="2d",(F31*(0.8+($D$6/14000)))/(36+9*G31),F31/E31) -> 0.024444444 | I31: Usar h = | J31: =MAX(0.12,ROUND(H31,2)) -> 0.12 | L31: 0.3 | M31: 0.6 | N31: =+F31*J31*J31*J31/12 -> 0.000144 | O31: =+IF(4*J31>=M31-J31,M31-J31,4*J31)*2+L31 -> 1.26 | P31: =+M31-(0.5*(((O31-L31)*J31*J31)+L31*M31*M31)/((O31-L31)*J31+L31*M31)) -> 0.39365854 | Q31: =+(O31-L31)*J31*J31*J31/12+L31*M31*M31*M31/12+(O31-L31)*J31*POWER(M31-J31*0.5-P31,2)+L31*M31*POWER(P31-0.5*M31,2) -> 0.0095842888 | R31: =+Q31/N31 -> 66.557561 | S31: =+F31*J31*J31*J31*0.5/12 -> 7.2e-05 | T31: =+IF(4*J31>=M31-J31,M31-J31,4*J31)+L31 -> 0.78 | U31: =+M31-(0.5*(((T31-L31)*J31*J31)+L31*M31*M31)/((T31-L31)*J31+L31*M31)) -> 0.35818182 | V31: =+(T31-L31)*J31*J31*J31/12+L31*M31*M31*M31/12+(T31-L31)*J31*POWER(M31-J31*0.5-U31,2)+L31*M31*POWER(U31-0.5*M31,2) -> 0.0079825745 | W31: =+V31/S31 -> 110.86909 | X31: 2 | Y31: 2 | Z31: =+(X31*R31+Y31*W31)/4 -> 88.713326 | AA31: =+(F31*(0.8+($D$6/14000)))/(36+5*((IF(Z31>2,2,Z31))-0.2)*G31) -> 0.024444444
A32: 24 | B32: 1 | C32: 1 | D32: =IF((MAX(B32:C32)/MIN(B32:C32))>2,"1D","2D") -> 2D | E32: =IF(D32="2D","N.A.",10) -> N.A. | F32: =IF(D32="1D",MIN(B32:C32),MAX(B32:C32)) -> 1 | G32: =MAX(B32:C32)/MIN(B32:C32) -> 1 | H32: =IF(D32="2d",(F32*(0.8+($D$6/14000)))/(36+9*G32),F32/E32) -> 0.024444444 | I32: Usar h = | J32: =MAX(0.12,ROUND(H32,2)) -> 0.12 | L32: 0.3 | M32: 0.6 | N32: =+F32*J32*J32*J32/12 -> 0.000144 | O32: =+IF(4*J32>=M32-J32,M32-J32,4*J32)*2+L32 -> 1.26 | P32: =+M32-(0.5*(((O32-L32)*J32*J32)+L32*M32*M32)/((O32-L32)*J32+L32*M32)) -> 0.39365854 | Q32: =+(O32-L32)*J32*J32*J32/12+L32*M32*M32*M32/12+(O32-L32)*J32*POWER(M32-J32*0.5-P32,2)+L32*M32*POWER(P32-0.5*M32,2) -> 0.0095842888 | R32: =+Q32/N32 -> 66.557561 | S32: =+F32*J32*J32*J32*0.5/12 -> 7.2e-05 | T32: =+IF(4*J32>=M32-J32,M32-J32,4*J32)+L32 -> 0.78 | U32: =+M32-(0.5*(((T32-L32)*J32*J32)+L32*M32*M32)/((T32-L32)*J32+L32*M32)) -> 0.35818182 | V32: =+(T32-L32)*J32*J32*J32/12+L32*M32*M32*M32/12+(T32-L32)*J32*POWER(M32-J32*0.5-U32,2)+L32*M32*POWER(U32-0.5*M32,2) -> 0.0079825745 | W32: =+V32/S32 -> 110.86909 | X32: 2 | Y32: 2 | Z32: =+(X32*R32+Y32*W32)/4 -> 88.713326 | AA32: =+(F32*(0.8+($D$6/14000)))/(36+5*((IF(Z32>2,2,Z32))-0.2)*G32) -> 0.024444444
A33: 25 | B33: 1 | C33: 1 | D33: =IF((MAX(B33:C33)/MIN(B33:C33))>2,"1D","2D") -> 2D | E33: =IF(D33="2D","N.A.",10) -> N.A. | F33: =IF(D33="1D",MIN(B33:C33),MAX(B33:C33)) -> 1 | G33: =MAX(B33:C33)/MIN(B33:C33) -> 1 | H33: =IF(D33="2d",(F33*(0.8+($D$6/14000)))/(36+9*G33),F33/E33) -> 0.024444444 | I33: Usar h = | J33: =MAX(0.12,ROUND(H33,2)) -> 0.12 | L33: 0.3 | M33: 0.6 | N33: =+F33*J33*J33*J33/12 -> 0.000144 | O33: =+IF(4*J33>=M33-J33,M33-J33,4*J33)*2+L33 -> 1.26 | P33: =+M33-(0.5*(((O33-L33)*J33*J33)+L33*M33*M33)/((O33-L33)*J33+L33*M33)) -> 0.39365854 | Q33: =+(O33-L33)*J33*J33*J33/12+L33*M33*M33*M33/12+(O33-L33)*J33*POWER(M33-J33*0.5-P33,2)+L33*M33*POWER(P33-0.5*M33,2) -> 0.0095842888 | R33: =+Q33/N33 -> 66.557561 | S33: =+F33*J33*J33*J33*0.5/12 -> 7.2e-05 | T33: =+IF(4*J33>=M33-J33,M33-J33,4*J33)+L33 -> 0.78 | U33: =+M33-(0.5*(((T33-L33)*J33*J33)+L33*M33*M33)/((T33-L33)*J33+L33*M33)) -> 0.35818182 | V33: =+(T33-L33)*J33*J33*J33/12+L33*M33*M33*M33/12+(T33-L33)*J33*POWER(M33-J33*0.5-U33,2)+L33*M33*POWER(U33-0.5*M33,2) -> 0.0079825745 | W33: =+V33/S33 -> 110.86909 | X33: 2 | Y33: 2 | Z33: =+(X33*R33+Y33*W33)/4 -> 88.713326 | AA33: =+(F33*(0.8+($D$6/14000)))/(36+5*((IF(Z33>2,2,Z33))-0.2)*G33) -> 0.024444444
A34: 26 | B34: 1 | C34: 1 | D34: =IF((MAX(B34:C34)/MIN(B34:C34))>2,"1D","2D") -> 2D | E34: =IF(D34="2D","N.A.",10) -> N.A. | F34: =IF(D34="1D",MIN(B34:C34),MAX(B34:C34)) -> 1 | G34: =MAX(B34:C34)/MIN(B34:C34) -> 1 | H34: =IF(D34="2d",(F34*(0.8+($D$6/14000)))/(36+9*G34),F34/E34) -> 0.024444444 | I34: Usar h = | J34: =MAX(0.12,ROUND(H34,2)) -> 0.12 | L34: 0.3 | M34: 0.6 | N34: =+F34*J34*J34*J34/12 -> 0.000144 | O34: =+IF(4*J34>=M34-J34,M34-J34,4*J34)*2+L34 -> 1.26 | P34: =+M34-(0.5*(((O34-L34)*J34*J34)+L34*M34*M34)/((O34-L34)*J34+L34*M34)) -> 0.39365854 | Q34: =+(O34-L34)*J34*J34*J34/12+L34*M34*M34*M34/12+(O34-L34)*J34*POWER(M34-J34*0.5-P34,2)+L34*M34*POWER(P34-0.5*M34,2) -> 0.0095842888 | R34: =+Q34/N34 -> 66.557561 | S34: =+F34*J34*J34*J34*0.5/12 -> 7.2e-05 | T34: =+IF(4*J34>=M34-J34,M34-J34,4*J34)+L34 -> 0.78 | U34: =+M34-(0.5*(((T34-L34)*J34*J34)+L34*M34*M34)/((T34-L34)*J34+L34*M34)) -> 0.35818182 | V34: =+(T34-L34)*J34*J34*J34/12+L34*M34*M34*M34/12+(T34-L34)*J34*POWER(M34-J34*0.5-U34,2)+L34*M34*POWER(U34-0.5*M34,2) -> 0.0079825745 | W34: =+V34/S34 -> 110.86909 | X34: 2 | Y34: 2 | Z34: =+(X34*R34+Y34*W34)/4 -> 88.713326 | AA34: =+(F34*(0.8+($D$6/14000)))/(36+5*((IF(Z34>2,2,Z34))-0.2)*G34) -> 0.024444444
A35: 27 | B35: 1 | C35: 1 | D35: =IF((MAX(B35:C35)/MIN(B35:C35))>2,"1D","2D") -> 2D | E35: =IF(D35="2D","N.A.",10) -> N.A. | F35: =IF(D35="1D",MIN(B35:C35),MAX(B35:C35)) -> 1 | G35: =MAX(B35:C35)/MIN(B35:C35) -> 1 | H35: =IF(D35="2d",(F35*(0.8+($D$6/14000)))/(36+9*G35),F35/E35) -> 0.024444444 | I35: Usar h = | J35: =MAX(0.12,ROUND(H35,2)) -> 0.12 | L35: 0.3 | M35: 0.6 | N35: =+F35*J35*J35*J35/12 -> 0.000144 | O35: =+IF(4*J35>=M35-J35,M35-J35,4*J35)*2+L35 -> 1.26 | P35: =+M35-(0.5*(((O35-L35)*J35*J35)+L35*M35*M35)/((O35-L35)*J35+L35*M35)) -> 0.39365854 | Q35: =+(O35-L35)*J35*J35*J35/12+L35*M35*M35*M35/12+(O35-L35)*J35*POWER(M35-J35*0.5-P35,2)+L35*M35*POWER(P35-0.5*M35,2) -> 0.0095842888 | R35: =+Q35/N35 -> 66.557561 | S35: =+F35*J35*J35*J35*0.5/12 -> 7.2e-05 | T35: =+IF(4*J35>=M35-J35,M35-J35,4*J35)+L35 -> 0.78 | U35: =+M35-(0.5*(((T35-L35)*J35*J35)+L35*M35*M35)/((T35-L35)*J35+L35*M35)) -> 0.35818182 | V35: =+(T35-L35)*J35*J35*J35/12+L35*M35*M35*M35/12+(T35-L35)*J35*POWER(M35-J35*0.5-U35,2)+L35*M35*POWER(U35-0.5*M35,2) -> 0.0079825745 | W35: =+V35/S35 -> 110.86909 | X35: 2 | Y35: 2 | Z35: =+(X35*R35+Y35*W35)/4 -> 88.713326 | AA35: =+(F35*(0.8+($D$6/14000)))/(36+5*((IF(Z35>2,2,Z35))-0.2)*G35) -> 0.024444444
... A58: 50 | B58: 1 | C58: 1 | D58: =IF((MAX(B58:C58)/MIN(B58:C58))>2,"1D","2D") -> 2D | E58: =IF(D58="2D","N.A.",10) -> N.A. | F58: =IF(D58="1D",MIN(B58:C58),MAX(B58:C58)) -> 1 | G58: =MAX(B58:C58)/MIN(B58:C58) -> 1 | H58: =IF(D58="2d",(F58*(0.8+($D$6/14000)))/(36+9*G58),F58/E58) -> 0.024444444 | I58: Usar h = | J58: =MAX(0.12,ROUND(H58,2)) -> 0.12 | L58: 0.3 | M58: 0.6 | N58: =+F58*J58*J58*J58/12 -> 0.000144 | O58: =+IF(4*J58>=M58-J58,M58-J58,4*J58)*2+L58 -> 1.26 | P58: =+M58-(0.5*(((O58-L58)*J58*J58)+L58*M58*M58)/((O58-L58)*J58+L58*M58)) -> 0.39365854 | Q58: =+(O58-L58)*J58*J58*J58/12+L58*M58*M58*M58/12+(O58-L58)*J58*POWER(M58-J58*0.5-P58,2)+L58*M58*POWER(P58-0.5*M58,2) -> 0.0095842888 | R58: =+Q58/N58 -> 66.557561 | S58: =+F58*J58*J58*J58*0.5/12 -> 7.2e-05 | T58: =+IF(4*J58>=M58-J58,M58-J58,4*J58)+L58 -> 0.78 | U58: =+M58-(0.5*(((T58-L58)*J58*J58)+L58*M58*M58)/((T58-L58)*J58+L58*M58)) -> 0.35818182 | V58: =+(T58-L58)*J58*J58*J58/12+L58*M58*M58*M58/12+(T58-L58)*J58*POWER(M58-J58*0.5-U58,2)+L58*M58*POWER(U58-0.5*M58,2) -> 0.0079825745 | W58: =+V58/S58 -> 110.86909 | X58: 2 | Y58: 2 | Z58: =+(X58*R58+Y58*W58)/4 -> 88.713326 | AA58: =+(F58*(0.8+($D$6/14000)))/(36+5*((IF(Z58>2,2,Z58))-0.2)*G58) -> 0.024444444

Sheet Espesor E2
AB1: {=_xlfn.TEXTAFTER(CELL("filename",S2),"]")} -> Espesor E2
B2: ='Espesor Earlette'!B2:D2 -> INGENIERO DEMO | E2: Proyecto: | G2: ='Espesor Earlette'!G2:I2 -> Proyecto Demo | J2: Pag. | AB2: =_xlfn.TEXTAFTER(AB1,"Espesor") -> E2 | AC2: =_xlfn.CONCAT(AB2," ","/") -> E2 /
B3: ='Espesor Earlette'!B3 -> INGENIERO CIVIL | E3: Fecha : | G3: ='Espesor Earlette'!G3:I3 -> 45904 | J3: 1
B4: CODIA: | C4: ='Espesor Earlette'!C4 -> 0 | E4: Desc. : | F4: =_xlfn.CONCAT("Espesor"," ","de"," ","Losas"," ",AB2) -> Espesor de Losas E2
A6: Cant. de Losas: | B6: =IF(COUNTIFS(C9:C58,"<>1", B9:B58,"<>1")=0, 50, COUNTIFS(C9:C58,"<>1", B9:B58,"<>1")) -> 50 | C6: Fy = | D6: 4200 | E6: Kg/cm²
N7: T | S7: L
A8: LOSA | B8: Lx | C8: Ly | D8: Cond. | E8: K | F8: Ln | G8: b | H8: h [cm] | L8: bw | M8: H | N8: Is | O8: B | P8: yt | Q8: Ib | R8: α | S8: Is | T8: B | U8: yt | V8: Ib | W8: α | X8: T | Y8: L | Z8: αfm | AA8: H
A9: 1 | B9: 1 | C9: 1 | D9: =IF((MAX(B9:C9)/MIN(B9:C9))>2,"1D","2D") -> 2D | E9: =IF(D9="2D","N.A.",10) -> N.A. | F9: =IF(D9="1D",MIN(B9:C9),MAX(B9:C9)) -> 1 | G9: =MAX(B9:C9)/MIN(B9:C9) -> 1 | H9: =IF(D9="2d",(F9*(0.8+($D$6/14000)))/(36+9*G9),F9/E9) -> 0.024444444 | I9: Usar h = | J9: =MAX(0.12,ROUND(H9,2)) -> 0.12 | L9: 0.3 | M9: 0.6 | N9: =+F9*J9*J9*J9/12 -> 0.000144 | O9: =+IF(4*J9>=M9-J9,M9-J9,4*J9)*2+L9 -> 1.26 | P9: =+M9-(0.5*(((O9-L9)*J9*J9)+L9*M9*M9)/((O9-L9)*J9+L9*M9)) -> 0.39365854 | Q9: =+(O9-L9)*J9*J9*J9/12+L9*M9*M9*M9/12+(O9-L9)*J9*POWER(M9-J9*0.5-P9,2)+L9*M9*POWER(P9-0.5*M9,2) -> 0.0095842888 | R9: =+Q9/N9 -> 66.557561 | S9: =+F9*J9*J9*J9*0.5/12 -> 7.2e-05 | T9: =+IF(4*J9>=M9-J9,M9-J9,4*J9)+L9 -> 0.78 | U9: =+M9-(0.5*(((T9-L9)*J9*J9)+L9*M9*M9)/((T9-L9)*J9+L9*M9)) -> 0.35818182 | V9: =+(T9-L9)*J9*J9*J9/12+L9*M9*M9*M9/12+(T9-L9)*J9*POWER(M9-J9*0.5-U9,2)+L9*M9*POWER(U9-0.5*M9,2) -> 0.0079825745 | W9: =+V9/S9 -> 110.86909 | X9: 2 | Y9: 2 | Z9: =+(X9*R9+Y9*W9)/4 -> 88.713326 | AA9: =+(F9*(0.8+($D$6/14000)))/(36+5*((IF(Z9>2,2,Z9))-0.2)*G9) -> 0.024444444
A10: 2 | B10: 1 | C10: 1 | D10: =IF((MAX(B10:C10)/MIN(B10:C10))>2,"1D","2D") -> 2D | E10: =IF(D10="2D","N.A.",10) -> N.A. | F10: =IF(D10="1D",MIN(B10:C10),MAX(B10:C10)) -> 1 | G10: =MAX(B10:C10)/MIN(B10:C10) -> 1 | H10: =IF(D10="2d",(F10*(0.8+($D$6/14000)))/(36+9*G10),F10/E10) -> 0.024444444 | I10: Usar h = | J10: =MAX(0.12,ROUND(H10,2)) -> 0.12 | L10: 0.3 | M10: 0.6 | N10: =+F10*J10*J10*J10/12 -> 0.000144 | O10: =+IF(4*J10>=M10-J10,M10-J10,4*J10)*2+L10 -> 1.26 | P10: =+M10-(0.5*(((O10-L10)*J10*J10)+L10*M10*M10)/((O10-L10)*J10+L10*M10)) -> 0.39365854 | Q10: =+(O10-L10)*J10*J10*J10/12+L10*M10*M10*M10/12+(O10-L10)*J10*POWER(M10-J10*0.5-P10,2)+L10*M10*POWER(P10-0.5*M10,2) -> 0.0095842888 | R10: =+Q10/N10 -> 66.557561 | S10: =+F10*J10*J10*J10*0.5/12 -> 7.2e-05 | T10: =+IF(4*J10>=M10-J10,M10-J10,4*J10)+L10 -> 0.78 | U10: =+M10-(0.5*(((T10-L10)*J10*J10)+L10*M10*M10)/((T10-L10)*J10+L10*M10)) -> 0.35818182 | V10: =+(T10-L10)*J10*J10*J10/12+L10*M10*M10*M10/12+(T10-L10)*J10*POWER(M10-J10*0.5-U10,2)+L10*M10*POWER(U10-0.5*M10,2) -> 0.0079825745 | W10: =+V10/S10 -> 110.86909 | X10: 2 | Y10: 2 | Z10: =+(X10*R10+Y10*W10)/4 -> 88.713326 | AA10: =+(F10*(0.8+($D$6/14000)))/(36+5*((IF(Z10>2,2,Z10))-0.2)*G10) -> 0.024444444
A11: 3 | B11: 1 | C11: 1 | D11: =IF((MAX(B11:C11)/MIN(B11:C11))>2,"1D","2D") -> 2D | E11: =IF(D11="2D","N.A.",10) -> N.A. | F11: =IF(D11="1D",MIN(B11:C11),MAX(B11:C11)) -> 1 | G11: =MAX(B11:C11)/MIN(B11:C11) -> 1 | H11: =IF(D11="2d",(F11*(0.8+($D$6/14000)))/(36+9*G11),F11/E11) -> 0.024444444 | I11: Usar h = | J11: =MAX(0.12,ROUND(H11,2)) -> 0.12 | L11: 0.3 | M11: 0.6 | N11: =+F11*J11*J11*J11/12 -> 0.000144 | O11: =+IF(4*J11>=M11-J11,M11-J11,4*J11)*2+L11 -> 1.26 | P11: =+M11-(0.5*(((O11-L11)*J11*J11)+L11*M11*M11)/((O11-L11)*J11+L11*M11)) -> 0.39365854 | Q11: =+(O11-L11)*J11*J11*J11/12+L11*M11*M11*M11/12+(O11-L11)*J11*POWER(M11-J11*0.5-P11,2)+L11*M11*POWER(P11-0.5*M11,2) -> 0.0095842888 | R11: =+Q11/N11 -> 66.557561 | S11: =+F11*J11*J11*J11*0.5/12 -> 7.2e-05 | T11: =+IF(4*J11>=M11-J11,M11-J11,4*J11)+L11 -> 0.78 | U11: =+M11-(0.5*(((T11-L11)*J11*J11)+L11*M11*M11)/((T11-L11)*J11+L11*M11)) -> 0.35818182 | V11: =+(T11-L11)*J11*J11*J11/12+L11*M11*M11*M11/12+(T11-L11)*J11*POWER(M11-J11*0.5-U11,2)+L11*M11*POWER(U11-0.5*M11,2) -> 0.0079825745 | W11: =+V11/S11 -> 110.86909 | X11: 2 | Y11: 2 | Z11: =+(X11*R11+Y11*W11)/4 -> 88.713326 | AA11: =+(F11*(0.8+($D$6/14000)))/(36+5*((IF(Z11>2,2,Z11))-0.2)*G11) -> 0.024444444
A12: 4 | B12: 1 | C12: 1 | D12: =IF((MAX(B12:C12)/MIN(B12:C12))>2,"1D","2D") -> 2D | E12: =IF(D12="2D","N.A.",10) -> N.A. | F12: =IF(D12="1D",MIN(B12:C12),MAX(B12:C12)) -> 1 | G12: =MAX(B12:C12)/MIN(B12:C12) -> 1 | H12: =IF(D12="2d",(F12*(0.8+($D$6/14000)))/(36+9*G12),F12/E12) -> 0.024444444 | I12: Usar h = | J12: =MAX(0.12,ROUND(H12,2)) -> 0.12 | L12: 0.3 | M12: 0.6 | N12: =+F12*J12*J12*J12/12 -> 0.000144 | O12: =+IF(4*J12>=M12-J12,M12-J12,4*J12)*2+L12 -> 1.26 | P12: =+M12-(0.5*(((O12-L12)*J12*J12)+L12*M12*M12)/((O12-L12)*J12+L12*M12)) -> 0.39365854 | Q12: =+(O12-L12)*J12*J12*J12/12+L12*M12*M12*M12/12+(O12-L12)*J12*POWER(M12-J12*0.5-P12,2)+L12*M12*POWER(P12-0.5*M12,2) -> 0.0095842888 | R12: =+Q12/N12 -> 66.557561 | S12: =+F12*J12*J12*J12*0.5/12 -> 7.2e-05 | T12: =+IF(4*J12>=M12-J12,M12-J12,4*J12)+L12 -> 0.78 | U12: =+M12-(0.5*(((T12-L12)*J12*J12)+L12*M12*M12)/((T12-L12)*J12+L12*M12)) -> 0.35818182 | V12: =+(T12-L12)*J12*J12*J12/12+L12*M12*M12*M12/12+(T12-L12)*J12*POWER(M12-J12*0.5-U12,2)+L12*M12*POWER(U12-0.5*M12,2) -> 0.0079825745 | W12: =+V12/S12 -> 110.86909 | X12: 2 | Y12: 2 | Z12: =+(X12*R12+Y12*W12)/4 -> 88.713326 | AA12: =+(F12*(0.8+($D$6/14000)))/(36+5*((IF(Z12>2,2,Z12))-0.2)*G12) -> 0.024444444
A13: 5 | B13: 1 | C13: 1 | D13: =IF((MAX(B13:C13)/MIN(B13:C13))>2,"1D","2D") -> 2D | E13: =IF(D13="2D","N.A.",10) -> N.A. | F13: =IF(D13="1D",MIN(B13:C13),MAX(B13:C13)) -> 1 | G13: =MAX(B13:C13)/MIN(B13:C13) -> 1 | H13: =IF(D13="2d",(F13*(0.8+($D$6/14000)))/(36+9*G13),F13/E13) -> 0.024444444 | I13: Usar h = | J13: =MAX(0.12,ROUND(H13,2)) -> 0.12 | L13: 0.3 | M13: 0.6 | N13: =+F13*J13*J13*J13/12 -> 0.000144 | O13: =+IF(4*J13>=M13-J13,M13-J13,4*J13)*2+L13 -> 1.26 | P13: =+M13-(0.5*(((O13-L13)*J13*J13)+L13*M13*M13)/((O13-L13)*J13+L13*M13)) -> 0.39365854 | Q13: =+(O13-L13)*J13*J13*J13/12+L13*M13*M13*M13/12+(O13-L13)*J13*POWER(M13-J13*0.5-P13,2)+L13*M13*POWER(P13-0.5*M13,2) -> 0.0095842888 | R13: =+Q13/N13 -> 66.557561 | S13: =+F13*J13*J13*J13*0.5/12 -> 7.2e-05 | T13: =+IF(4*J13>=M13-J13,M13-J13,4*J13)+L13 -> 0.78 | U13: =+M13-(0.5*(((T13-L13)*J13*J13)+L13*M13*M13)/((T13-L13)*J13+L13*M13)) -> 0.35818182 | V13: =+(T13-L13)*J13*J13*J13/12+L13*M13*M13*M13/12+(T13-L13)*J13*POWER(M13-J13*0.5-U13,2)+L13*M13*POWER(U13-0.5*M13,2) -> 0.0079825745 | W13: =+V13/S13 -> 110.86909 | X13: 2 | Y13: 2 | Z13: =+(X13*R13+Y13*W13)/4 -> 88.713326 | AA13: =+(F13*(0.8+($D$6/14000)))/(36+5*((IF(Z13>2,2,Z13))-0.2)*G13) -> 0.024444444
A14: 6 | B14: 1 | C14: 1 | D14: =IF((MAX(B14:C14)/MIN(B14:C14))>2,"1D","2D") -> 2D | E14: =IF(D14="2D","N.A.",10) -> N.A. | F14: =IF(D14="1D",MIN(B14:C14),MAX(B14:C14)) -> 1 | G14: =MAX(B14:C14)/MIN(B14:C14) -> 1 | H14: =IF(D14="2d",(F14*(0.8+($D$6/14000)))/(36+9*G14),F14/E14) -> 0.024444444 | I14: Usar h = | J14: =MAX(0.12,ROUND(H14,2)) -> 0.12 | L14: 0.3 | M14: 0.6 | N14: =+F14*J14*J14*J14/12 -> 0.000144 | O14: =+IF(4*J14>=M14-J14,M14-J14,4*J14)*2+L14 -> 1.26 | P14: =+M14-(0.5*(((O14-L14)*J14*J14)+L14*M14*M14)/((O14-L14)*J14+L14*M14)) -> 0.39365854 | Q14: =+(O14-L14)*J14*J14*J14/12+L14*M14*M14*M14/12+(O14-L14)*J14*POWER(M14-J14*0.5-P14,2)+L14*M14*POWER(P14-0.5*M14,2) -> 0.0095842888 | R14: =+Q14/N14 -> 66.557561 | S14: =+F14*J14*J14*J14*0.5/12 -> 7.2e-05 | T14: =+IF(4*J14>=M14-J14,M14-J14,4*J14)+L14 -> 0.78 | U14: =+M14-(0.5*(((T14-L14)*J14*J14)+L14*M14*M14)/((T14-L14)*J14+L14*M14)) -> 0.35818182 | V14: =+(T14-L14)*J14*J14*J14/12+L14*M14*M14*M14/12+(T14-L14)*J14*POWER(M14-J14*0.5-U14,2)+L14*M14*POWER(U14-0.5*M14,2) -> 0.0079825745 | W14: =+V14/S14 -> 110.86909 | X14: 2 | Y14: 2 | Z14: =+(X14*R14+Y14*W14)/4 -> 88.713326 | AA14: =+(F14*(0.8+($D$6/14000)))/(36+5*((IF(Z14>2,2,Z14))-0.2)*G14) -> 0.024444444
A15: 7 | B15: 1 | C15: 1 | D15: =IF((MAX(B15:C15)/MIN(B15:C15))>2,"1D","2D") -> 2D | E15: =IF(D15="2D","N.A.",10) -> N.A. | F15: =IF(D15="1D",MIN(B15:C15),MAX(B15:C15)) -> 1 | G15: =MAX(B15:C15)/MIN(B15:C15) -> 1 | H15: =IF(D15="2d",(F15*(0.8+($D$6/14000)))/(36+9*G15),F15/E15) -> 0.024444444 | I15: Usar h = | J15: =MAX(0.12,ROUND(H15,2)) -> 0.12 | L15: 0.3 | M15: 0.6 | N15: =+F15*J15*J15*J15/12 -> 0.000144 | O15: =+IF(4*J15>=M15-J15,M15-J15,4*J15)*2+L15 -> 1.26 | P15: =+M15-(0.5*(((O15-L15)*J15*J15)+L15*M15*M15)/((O15-L15)*J15+L15*M15)) -> 0.39365854 | Q15: =+(O15-L15)*J15*J15*J15/12+L15*M15*M15*M15/12+(O15-L15)*J15*POWER(M15-J15*0.5-P15,2)+L15*M15*POWER(P15-0.5*M15,2) -> 0.0095842888 | R15: =+Q15/N15 -> 66.557561 | S15: =+F15*J15*J15*J15*0.5/12 -> 7.2e-05 | T15: =+IF(4*J15>=M15-J15,M15-J15,4*J15)+L15 -> 0.78 | U15: =+M15-(0.5*(((T15-L15)*J15*J15)+L15*M15*M15)/((T15-L15)*J15+L15*M15)) -> 0.35818182 | V15: =+(T15-L15)*J15*J15*J15/12+L15*M15*M15*M15/12+(T15-L15)*J15*POWER(M15-J15*0.5-U15,2)+L15*M15*POWER(U15-0.5*M15,2) -> 0.0079825745 | W15: =+V15/S15 -> 110.86909 | X15: 2 | Y15: 2 | Z15: =+(X15*R15+Y15*W15)/4 -> 88.713326 | AA15: =+(F15*(0.8+($D$6/14000)))/(36+5*((IF(Z15>2,2,Z15))-0.2)*G15) -> 0.024444444
A16: 8 | B16: 1 | C16: 1 | D16: =IF((MAX(B16:C16)/MIN(B16:C16))>2,"1D","2D") -> 2D | E16: =IF(D16="2D","N.A.",10) -> N.A. | F16: =IF(D16="1D",MIN(B16:C16),MAX(B16:C16)) -> 1 | G16: =MAX(B16:C16)/MIN(B16:C16) -> 1 | H16: =IF(D16="2d",(F16*(0.8+($D$6/14000)))/(36+9*G16),F16/E16) -> 0.024444444 | I16: Usar h = | J16: =MAX(0.12,ROUND(H16,2)) -> 0.12 | L16: 0.3 | M16: 0.6 | N16: =+F16*J16*J16*J16/12 -> 0.000144 | O16: =+IF(4*J16>=M16-J16,M16-J16,4*J16)*2+L16 -> 1.26 | P16: =+M16-(0.5*(((O16-L16)*J16*J16)+L16*M16*M16)/((O16-L16)*J16+L16*M16)) -> 0.39365854 | Q16: =+(O16-L16)*J16*J16*J16/12+L16*M16*M16*M16/12+(O16-L16)*J16*POWER(M16-J16*0.5-P16,2)+L16*M16*POWER(P16-0.5*M16,2) -> 0.0095842888 | R16: =+Q16/N16 -> 66.557561 | S16: =+F16*J16*J16*J16*0.5/12 -> 7.2e-05 | T16: =+IF(4*J16>=M16-J16,M16-J16,4*J16)+L16 -> 0.78 | U16: =+M16-(0.5*(((T16-L16)*J16*J16)+L16*M16*M16)/((T16-L16)*J16+L16*M16)) -> 0.35818182 | V16: =+(T16-L16)*J16*J16*J16/12+L16*M16*M16*M16/12+(T16-L16)*J16*POWER(M16-J16*0.5-U16,2)+L16*M16*POWER(U16-0.5*M16,2) -> 0.0079825745 | W16: =+V16/S16 -> 110.86909 | X16: 2 | Y16: 2 | Z16: =+(X16*R16+Y16*W16)/4 -> 88.713326 | AA16: =+(F16*(0.8+($D$6/14000)))/(36+5*((IF(Z16>2,2,Z16))-0.2)*G16) -> 0.024444444
A17: 9 | B17: 1 | C17: 1 | D17: =IF((MAX(B17:C17)/MIN(B17:C17))>2,"1D","2D") -> 2D | E17: =IF(D17="2D","N.A.",10) -> N.A. | F17: =IF(D17="1D",MIN(B17:C17),MAX(B17:C17)) -> 1 | G17: =MAX(B17:C17)/MIN(B17:C17) -> 1 | H17: =IF(D17="2d",(F17*(0.8+($D$6/14000)))/(36+9*G17),F17/E17) -> 0.024444444 | I17: Usar h = | J17: =MAX(0.12,ROUND(H17,2)) -> 0.12 | L17: 0.3 | M17: 0.6 | N17: =+F17*J17*J17*J17/12 -> 0.000144 | O17: =+IF(4*J17>=M17-J17,M17-J17,4*J17)*2+L17 -> 1.26 | P17: =+M17-(0.5*(((O17-L17)*J17*J17)+L17*M17*M17)/((O17-L17)*J17+L17*M17)) -> 0.39365854 | Q17: =+(O17-L17)*J17*J17*J17/12+L17*M17*M17*M17/12+(O17-L17)*J17*POWER(M17-J17*0.5-P17,2)+L17*M17*POWER(P17-0.5*M17,2) -> 0.0095842888 | R17: =+Q17/N17 -> 66.557561 | S17: =+F17*J17*J17*J17*0.5/12 -> 7.2e-05 | T17: =+IF(4*J17>=M17-J17,M17-J17,4*J17)+L17 -> 0.78 | U17: =+M17-(0.5*(((T17-L17)*J17*J17)+L17*M17*M17)/((T17-L17)*J17+L17*M17)) -> 0.35818182 | V17: =+(T17-L17)*J17*J17*J17/12+L17*M17*M17*M17/12+(T17-L17)*J17*POWER(M17-J17*0.5-U17,2)+L17*M17*POWER(U17-0.5*M17,2) -> 0.0079825745 | W17: =+V17/S17 -> 110.86909 | X17: 2 | Y17: 2 | Z17: =+(X17*R17+Y17*W17)/4 -> 88.713326 | AA17: =+(F17*(0.8+($D$6/14000)))/(36+5*((IF(Z17>2,2,Z17))-0.2)*G17) -> 0.024444444
A18: 10 | B18: 1 | C18: 1 | D18: =IF((MAX(B18:C18)/MIN(B18:C18))>2,"1D","2D") -> 2D | E18: =IF(D18="2D","N.A.",10) -> N.A. | F18: =IF(D18="1D",MIN(B18:C18),MAX(B18:C18)) -> 1 | G18: =MAX(B18:C18)/MIN(B18:C18) -> 1 | H18: =IF(D18="2d",(F18*(0.8+($D$6/14000)))/(36+9*G18),F18/E18) -> 0.024444444 | I18: Usar h = | J18: =MAX(0.12,ROUND(H18,2)) -> 0.12 | L18: 0.3 | M18: 0.6 | N18: =+F18*J18*J18*J18/12 -> 0.000144 | O18: =+IF(4*J18>=M18-J18,M18-J18,4*J18)*2+L18 -> 1.26 | P18: =+M18-(0.5*(((O18-L18)*J18*J18)+L18*M18*M18)/((O18-L18)*J18+L18*M18)) -> 0.39365854 | Q18: =+(O18-L18)*J18*J18*J18/12+L18*M18*M18*M18/12+(O18-L18)*J18*POWER(M18-J18*0.5-P18,2)+L18*M18*POWER(P18-0.5*M18,2) -> 0.0095842888 | R18: =+Q18/N18 -> 66.557561 | S18: =+F18*J18*J18*J18*0.5/12 -> 7.2e-05 | T18: =+IF(4*J18>=M18-J18,M18-J18,4*J18)+L18 -> 0.78 | U18: =+M18-(0.5*(((T18-L18)*J18*J18)+L18*M18*M18)/((T18-L18)*J18+L18*M18)) -> 0.35818182 | V18: =+(T18-L18)*J18*J18*J18/12+L18*M18*M18*M18/12+(T18-L18)*J18*POWER(M18-J18*0.5-U18,2)+L18*M18*POWER(U18-0.5*M18,2) -> 0.0079825745 | W18: =+V18/S18 -> 110.86909 | X18: 2 | Y18: 2 | Z18: =+(X18*R18+Y18*W18)/4 -> 88.713326 | AA18: =+(F18*(0.8+($D$6/14000)))/(36+5*((IF(Z18>2,2,Z18))-0.2)*G18) -> 0.024444444
A19: 11 | B19: 1 | C19: 1 | D19: =IF((MAX(B19:C19)/MIN(B19:C19))>2,"1D","2D") -> 2D | E19: =IF(D19="2D","N.A.",10) -> N.A. | F19: =IF(D19="1D",MIN(B19:C19),MAX(B19:C19)) -> 1 | G19: =MAX(B19:C19)/MIN(B19:C19) -> 1 | H19: =IF(D19="2d",(F19*(0.8+($D$6/14000)))/(36+9*G19),F19/E19) -> 0.024444444 | I19: Usar h = | J19: =MAX(0.12,ROUND(H19,2)) -> 0.12 | L19: 0.3 | M19: 0.6 | N19: =+F19*J19*J19*J19/12 -> 0.000144 | O19: =+IF(4*J19>=M19-J19,M19-J19,4*J19)*2+L19 -> 1.26 | P19: =+M19-(0.5*(((O19-L19)*J19*J19)+L19*M19*M19)/((O19-L19)*J19+L19*M19)) -> 0.39365854 | Q19: =+(O19-L19)*J19*J19*J19/12+L19*M19*M19*M19/12+(O19-L19)*J19*POWER(M19-J19*0.5-P19,2)+L19*M19*POWER(P19-0.5*M19,2) -> 0.0095842888 | R19: =+Q19/N19 -> 66.557561 | S19: =+F19*J19*J19*J19*0.5/12 -> 7.2e-05 | T19: =+IF(4*J19>=M19-J19,M19-J19,4*J19)+L19 -> 0.78 | U19: =+M19-(0.5*(((T19-L19)*J19*J19)+L19*M19*M19)/((T19-L19)*J19+L19*M19)) -> 0.35818182 | V19: =+(T19-L19)*J19*J19*J19/12+L19*M19*M19*M19/12+(T19-L19)*J19*POWER(M19-J19*0.5-U19,2)+L19*M19*POWER(U19-0.5*M19,2) -> 0.0079825745 | W19: =+V19/S19 -> 110.86909 | X19: 2 | Y19: 2 | Z19: =+(X19*R19+Y19*W19)/4 -> 88.713326 | AA19: =+(F19*(0.8+($D$6/14000)))/(36+5*((IF(Z19>2,2,Z19))-0.2)*G19) -> 0.024444444
A20: 12 | B20: 1 | C20: 1 | D20: =IF((MAX(B20:C20)/MIN(B20:C20))>2,"1D","2D") -> 2D | E20: =IF(D20="2D","N.A.",10) -> N.A. | F20: =IF(D20="1D",MIN(B20:C20),MAX(B20:C20)) -> 1 | G20: =MAX(B20:C20)/MIN(B20:C20) -> 1 | H20: =IF(D20="2d",(F20*(0.8+($D$6/14000)))/(36+9*G20),F20/E20) -> 0.024444444 | I20: Usar h = | J20: =MAX(0.12,ROUND(H20,2)) -> 0.12 | L20: 0.3 | M20: 0.6 | N20: =+F20*J20*J20*J20/12 -> 0.000144 | O20: =+IF(4*J20>=M20-J20,M20-J20,4*J20)*2+L20 -> 1.26 | P20: =+M20-(0.5*(((O20-L20)*J20*J20)+L20*M20*M20)/((O20-L20)*J20+L20*M20)) -> 0.39365854 | Q20: =+(O20-L20)*J20*J20*J20/12+L20*M20*M20*M20/12+(O20-L20)*J20*POWER(M20-J20*0.5-P20,2)+L20*M20*POWER(P20-0.5*M20,2) -> 0.0095842888 | R20: =+Q20/N20 -> 66.557561 | S20: =+F20*J20*J20*J20*0.5/12 -> 7.2e-05 | T20: =+IF(4*J20>=M20-J20,M20-J20,4*J20)+L20 -> 0.78 | U20: =+M20-(0.5*(((T20-L20)*J20*J20)+L20*M20*M20)/((T20-L20)*J20+L20*M20)) -> 0.35818182 | V20: =+(T20-L20)*J20*J20*J20/12+L20*M20*M20*M20/12+(T20-L20)*J20*POWER(M20-J20*0.5-U20,2)+L20*M20*POWER(U20-0.5*M20,2) -> 0.0079825745 | W20: =+V20/S20 -> 110.86909 | X20: 2 | Y20: 2 | Z20: =+(X20*R20+Y20*W20)/4 -> 88.713326 | AA20: =+(F20*(0.8+($D$6/14000)))/(36+5*((IF(Z20>2,2,Z20))-0.2)*G20) -> 0.024444444
... A58: 50 | B58: 1 | C58: 1 | D58: =IF((MAX(B58:C58)/MIN(B58:C58))>2,"1D","2D") -> 2D | E58: =IF(D58="2D","N.A.",10) -> N.A. | F58: =IF(D58="1D",MIN(B58:C58),MAX(B58:C58)) -> 1 | G58: =MAX(B58:C58)/MIN(B58:C58) -> 1 | H58: =IF(D58="2d",(F58*(0.8+($D$6/14000)))/(36+9*G58),F58/E58) -> 0.024444444 | I58: Usar h = | J58: =MAX(0.12,ROUND(H58,2)) -> 0.12 | L58: 0.3 | M58: 0.6 | N58: =+F58*J58*J58*J58/12 -> 0.000144 | O58: =+IF(4*J58>=M58-J58,M58-J58,4*J58)*2+L58 -> 1.26 | P58: =+M58-(0.5*(((O58-L58)*J58*J58)+L58*M58*M58)/((O58-L58)*J58+L58*M58)) -> 0.39365854 | Q58: =+(O58-L58)*J58*J58*J58/12+L58*M58*M58*M58/12+(O58-L58)*J58*POWER(M58-J58*0.5-P58,2)+L58*M58*POWER(P58-0.5*M58,2) -> 0.0095842888 | R58: =+Q58/N58 -> 66.557561 | S58: =+F58*J58*J58*J58*0.5/12 -> 7.2e-05 | T58: =+IF(4*J58>=M58-J58,M58-J58,4*J58)+L58 -> 0.78 | U58: =+M58-(0.5*(((T58-L58)*J58*J58)+L58*M58*M58)/((T58-L58)*J58+L58*M58)) -> 0.35818182 | V58: =+(T58-L58)*J58*J58*J58/12+L58*M58*M58*M58/12+(T58-L58)*J58*POWER(M58-J58*0.5-U58,2)+L58*M58*POWER(U58-0.5*M58,2) -> 0.0079825745 | W58: =+V58/S58 -> 110.86909 | X58: 2 | Y58: 2 | Z58: =+(X58*R58+Y58*W58)/4 -> 88.713326 | AA58: =+(F58*(0.8+($D$6/14000)))/(36+5*((IF(Z58>2,2,Z58))-0.2)*G58) -> 0.024444444

Sheet Espesor E3
AB1: {=_xlfn.TEXTAFTER(CELL("filename",S2),"]")} -> Espesor E3
B2: ='Espesor Earlette'!B2:D2 -> INGENIERO DEMO | E2: Proyecto: | G2: ='Espesor Earlette'!G2:I2 -> Proyecto Demo | J2: Pag. | AB2: =_xlfn.TEXTAFTER(AB1,"Espesor") -> E3 | AC2: =_xlfn.CONCAT(AB2," ","/") -> E3 /
B3: ='Espesor Earlette'!B3 -> INGENIERO CIVIL | E3: Fecha : | G3: ='Espesor Earlette'!G3:I3 -> 45904 | J3: 1
B4: CODIA: | C4: ='Espesor Earlette'!C4 -> 0 | E4: Desc. : | F4: =_xlfn.CONCAT("Espesor"," ","de"," ","Losas"," ",AB2) -> Espesor de Losas E3
A6: Cant. de Losas: | B6: =IF(COUNTIFS(C9:C58,"<>1", B9:B58,"<>1")=0, 50, COUNTIFS(C9:C58,"<>1", B9:B58,"<>1")) -> 50 | C6: Fy = | D6: 4200 | E6: Kg/cm²
N7: T | S7: L
A8: LOSA | B8: Lx | C8: Ly | D8: Cond. | E8: K | F8: Ln | G8: b | H8: h [cm] | L8: bw | M8: H | N8: Is | O8: B | P8: yt | Q8: Ib | R8: α | S8: Is | T8: B | U8: yt | V8: Ib | W8: α | X8: T | Y8: L | Z8: αfm | AA8: H
A9: 1 | B9: 1 | C9: 1 | D9: =IF((MAX(B9:C9)/MIN(B9:C9))>2,"1D","2D") -> 2D | E9: =IF(D9="2D","N.A.",10) -> N.A. | F9: =IF(D9="1D",MIN(B9:C9),MAX(B9:C9)) -> 1 | G9: =MAX(B9:C9)/MIN(B9:C9) -> 1 | H9: =IF(D9="2d",(F9*(0.8+($D$6/14000)))/(36+9*G9),F9/E9) -> 0.024444444 | I9: Usar h = | J9: =MAX(0.12,ROUND(H9,2)) -> 0.12 | L9: 0.3 | M9: 0.6 | N9: =+F9*J9*J9*J9/12 -> 0.000144 | O9: =+IF(4*J9>=M9-J9,M9-J9,4*J9)*2+L9 -> 1.26 | P9: =+M9-(0.5*(((O9-L9)*J9*J9)+L9*M9*M9)/((O9-L9)*J9+L9*M9)) -> 0.39365854 | Q9: =+(O9-L9)*J9*J9*J9/12+L9*M9*M9*M9/12+(O9-L9)*J9*POWER(M9-J9*0.5-P9,2)+L9*M9*POWER(P9-0.5*M9,2) -> 0.0095842888 | R9: =+Q9/N9 -> 66.557561 | S9: =+F9*J9*J9*J9*0.5/12 -> 7.2e-05 | T9: =+IF(4*J9>=M9-J9,M9-J9,4*J9)+L9 -> 0.78 | U9: =+M9-(0.5*(((T9-L9)*J9*J9)+L9*M9*M9)/((T9-L9)*J9+L9*M9)) -> 0.35818182 | V9: =+(T9-L9)*J9*J9*J9/12+L9*M9*M9*M9/12+(T9-L9)*J9*POWER(M9-J9*0.5-U9,2)+L9*M9*POWER(U9-0.5*M9,2) -> 0.0079825745 | W9: =+V9/S9 -> 110.86909 | X9: 2 | Y9: 2 | Z9: =+(X9*R9+Y9*W9)/4 -> 88.713326 | AA9: =+(F9*(0.8+($D$6/14000)))/(36+5*((IF(Z9>2,2,Z9))-0.2)*G9) -> 0.024444444
